Workbook

Sheet Léeme
A1: FORMATO DE MONITOREO COMERCIAL (Preventa y Venta) · borrador v1 · estructura tomada del PV-FR-59 del CUSI
A3: Hojas: TABLA GENERAL (muestra, niveles y resultados por asesor) · ASESOR 01 a 13 (una por asesor, hasta 6 conversaciones) · RESUMEN (cumplimiento por criterio y asesor) · CRITERIOS (catálogo, pesos, receptores de N/A y propiedades) · ESTRUCTURA WhatsApp / Llamada / Correo / Presencial (codificación en el formato de Estructuras.xlsx del CUSI) · VARIABLES (listas).
A4: Codificación: cada ítem tiene número por canal, propiedad con prefijo (wa_, ll_, co_, pr_), SI / NO / N/A con su peso y 'guion donde reposa' (número del ítem que recibe el peso si es N/A). Peso N/A = el peso que se traslada.
A6: Cómo se diligencia: en cada hoja ASESOR escribe el nombre, el canal y el tipo de gestión; luego, por cada conversación (columna Resultado, celdas amarillas) elige SI / NO / N/A. Todo lo demás se calcula.
A7: Una hoja ASESOR evalúa un canal y una gestión a la vez. Para evaluar a un asesor en otro canal, usa otra hoja ASESOR.
A9: Fase I (Control Habeas Data, HD): si algún HD es NO, el monitoreo queda reprobado (nota 0, nivel Crítico) y se escala a la Dirección Comercial.
A10: Indicadores ECU / ECN / ECC: % de conversaciones sin error. No reprueban por sí solos y no cambian la nota de la Fase II.
A11: Fase II: nota sobre 100 = promedio de las conversaciones (cada una suma 100 si cumple todo). Nota /300 = nota ×3, para usar los mismos niveles del CUSI.
A12: Aprobación: mínimo 85%. Debajo de 85% el asesor envía plan de acción. Los niveles (Crítico, Básico, En Alerta, Óptimo) son los del CUSI y se ven en TABLA GENERAL.
A13: N/A: el peso del ítem pasa completo al ítem indicado en CRITERIOS (columna Receptor). Los ítems fijos no admiten N/A y se marcan REVISAR si se usa.
A14: Alerta Dirección: se activa si hay un NO en HD-1, HD-2, HD-3 (filtro de seguridad / terceros), ECU-2 (maltrato) o ECC-2 (alteración de documentos): reporte inmediato con soportes.
A16: Pendiente de la operación: confirmar receptores de N/A propuestos, alcance de Cobranza / Llamada / Presencial, y los ítems que dependen de HubSpot.
A17: Celdas amarillas = para diligenciar. Rojo = críticos. Verde = ítems fijos.

Sheet TABLA GENERAL
B2: FORMATO DE MONITOREO COMERCIAL · TABLA GENERAL
B5: Muestra para el mes
B6: Mes evaluado | F6: Nivel | G6: Rango puntaje (/300) | H6: Porcentaje de cumplimiento | I6: Límite inferior | J6: Acción correctiva / sugerida
B7: Fecha del monitoreo | F7: Crítico | G7: 0 - 209 | H7: 0% - 69,7% | I7: 0 | J7: Llamado de atención, proceso disciplinario y plan de trabajo
B8: N manual (solo si no se diligencian los casos por asesor) | F8: Básico | G8: 210 - 239 | H8: 70% - 79,7% | I8: 0.7 | J8: Requiere retroalimentación
B9: N (población usada) | C9: =IF(SUM(E25:E37)>0,SUM(E25:E37),C8) | F9: En Alerta | G9: 240 - 275 | H9: 80% - 91,7% | I9: 0.8 | J9: Requiere compromisos
B10: Nivel de confianza | C10: 0.95 | F10: Óptimo | G10: 276 - 300 | H10: 92% - 100% | I10: 0.92 | J10: No requiere compromisos
B11: Z (automático) | C11: =VLOOKUP(C10,VARIABLES!$G$2:$H$4,2,0) | F11: Regla de aprobación: mínimo 85% (nota /100). Debajo de 85% el asesor envía plan de acción. Fase I (HD) con NO = Reprobado.
B12: p (probabilidad de éxito) | C12: 0.5
B13: q (probabilidad de fracaso) | C13: =1-C12
B14: E (margen de error) | C14: 0.1
B15: Asesores a evaluar | C15: =COUNTIF(B25:B37,"?*")
B16: n (muestra global) | C16: =IFERROR(ROUNDUP(C9*C11^2*C12*C13/(C14^2*(C9-1)+C11^2*C12*C13),0),"")
B17: Método de distribución por asesor | C17: Proporcional al volumen
B18: Mínimo de casos por asesor | C18: 3
B19: Muestra por asesor (si es igual para todos) | C19: =IFERROR(MAX(C18,ROUNDUP(C16/C15,0)),"")
B20: Muestra total a monitorear (suma por asesor) | C20: =SUM(F25:F37)
B21: Mínimo para aprobar (PV-IN-04) | C21: 0.85
B23: Tabla de resultados
B24: Asesor | C24: Canal | D24: Gestión | E24: Volumen de casos | F24: Muestra asignada | G24: Conversaciones evaluadas | H24: Fase I | I24: Nota /100 | J24: Nota /300 | K24: Nivel | L24: Estado | M24: ECU % | N24: ECN % | O24: ECC % | P24: Alerta Dirección
B25: =IF('ASESOR 01'!B3="","",'ASESOR 01'!B3) | C25: =IF('ASESOR 01'!B4="","",'ASESOR 01'!B4) | D25: =IF('ASESOR 01'!B5="","",'ASESOR 01'!B5) | F25: =IF(OR(B25="",$C$16=""),"",IF(SUM($E$25:$E$37)>0,MAX($C$18,ROUND($C$16*E25/SUM($E$25:$E$37),0)),$C$19)) | G25: ='ASESOR 01'!B7 | H25: ='ASESOR 01'!P3 | I25: ='ASESOR 01'!P4 | J25: ='ASESOR 01'!P5 | K25: ='ASESOR 01'!P6 | L25: ='ASESOR 01'!P7 | M25: ='ASESOR 01'!Z3 | N25: ='ASESOR 01'!Z4 | O25: ='ASESOR 01'!Z5 | P25: ='ASESOR 01'!Z6
B26: =IF('ASESOR 02'!B3="","",'ASESOR 02'!B3) | C26: =IF('ASESOR 02'!B4="","",'ASESOR 02'!B4) | D26: =IF('ASESOR 02'!B5="","",'ASESOR 02'!B5) | F26: =IF(OR(B26="",$C$16=""),"",IF(SUM($E$25:$E$37)>0,MAX($C$18,ROUND($C$16*E26/SUM($E$25:$E$37),0)),$C$19)) | G26: ='ASESOR 02'!B7 | H26: ='ASESOR 02'!P3 | I26: ='ASESOR 02'!P4 | J26: ='ASESOR 02'!P5 | K26: ='ASESOR 02'!P6 | L26: ='ASESOR 02'!P7 | M26: ='ASESOR 02'!Z3 | N26: ='ASESOR 02'!Z4 | O26: ='ASESOR 02'!Z5 | P26: ='ASESOR 02'!Z6
B27: =IF('ASESOR 03'!B3="","",'ASESOR 03'!B3) | C27: =IF('ASESOR 03'!B4="","",'ASESOR 03'!B4) | D27: =IF('ASESOR 03'!B5="","",'ASESOR 03'!B5) | F27: =IF(OR(B27="",$C$16=""),"",IF(SUM($E$25:$E$37)>0,MAX($C$18,ROUND($C$16*E27/SUM($E$25:$E$37),0)),$C$19)) | G27: ='ASESOR 03'!B7 | H27: ='ASESOR 03'!P3 | I27: ='ASESOR 03'!P4 | J27: ='ASESOR 03'!P5 | K27: ='ASESOR 03'!P6 | L27: ='ASESOR 03'!P7 | M27: ='ASESOR 03'!Z3 | N27: ='ASESOR 03'!Z4 | O27: ='ASESOR 03'!Z5 | P27: ='ASESOR 03'!Z6
B28: =IF('ASESOR 04'!B3="","",'ASESOR 04'!B3) | C28: =IF('ASESOR 04'!B4="","",'ASESOR 04'!B4) | D28: =IF('ASESOR 04'!B5="","",'ASESOR 04'!B5) | F28: =IF(OR(B28="",$C$16=""),"",IF(SUM($E$25:$E$37)>0,MAX($C$18,ROUND($C$16*E28/SUM($E$25:$E$37),0)),$C$19)) | G28: ='ASESOR 04'!B7 | H28: ='ASESOR 04'!P3 | I28: ='ASESOR 04'!P4 | J28: ='ASESOR 04'!P5 | K28: ='ASESOR 04'!P6 | L28: ='ASESOR 04'!P7 | M28: ='ASESOR 04'!Z3 | N28: ='ASESOR 04'!Z4 | O28: ='ASESOR 04'!Z5 | P28: ='ASESOR 04'!Z6
B29: =IF('ASESOR 05'!B3="","",'ASESOR 05'!B3) | C29: =IF('ASESOR 05'!B4="","",'ASESOR 05'!B4) | D29: =IF('ASESOR 05'!B5="","",'ASESOR 05'!B5) | F29: =IF(OR(B29="",$C$16=""),"",IF(SUM($E$25:$E$37)>0,MAX($C$18,ROUND($C$16*E29/SUM($E$25:$E$37),0)),$C$19)) | G29: ='ASESOR 05'!B7 | H29: ='ASESOR 05'!P3 | I29: ='ASESOR 05'!P4 | J29: ='ASESOR 05'!P5 | K29: ='ASESOR 05'!P6 | L29: ='ASESOR 05'!P7 | M29: ='ASESOR 05'!Z3 | N29: ='ASESOR 05'!Z4 | O29: ='ASESOR 05'!Z5 | P29: ='ASESOR 05'!Z6
B30: =IF('ASESOR 06'!B3="","",'ASESOR 06'!B3) | C30: =IF('ASESOR 06'!B4="","",'ASESOR 06'!B4) | D30: =IF('ASESOR 06'!B5="","",'ASESOR 06'!B5) | F30: =IF(OR(B30="",$C$16=""),"",IF(SUM($E$25:$E$37)>0,MAX($C$18,ROUND($C$16*E30/SUM($E$25:$E$37),0)),$C$19)) | G30: ='ASESOR 06'!B7 | H30: ='ASESOR 06'!P3 | I30: ='ASESOR 06'!P4 | J30: ='ASESOR 06'!P5 | K30: ='ASESOR 06'!P6 | L30: ='ASESOR 06'!P7 | M30: ='ASESOR 06'!Z3 | N30: ='ASESOR 06'!Z4 | O30: ='ASESOR 06'!Z5 | P30: ='ASESOR 06'!Z6
B31: =IF('ASESOR 07'!B3="","",'ASESOR 07'!B3) | C31: =IF('ASESOR 07'!B4="","",'ASESOR 07'!B4) | D31: =IF('ASESOR 07'!B5="","",'ASESOR 07'!B5) | F31: =IF(OR(B31="",$C$16=""),"",IF(SUM($E$25:$E$37)>0,MAX($C$18,ROUND($C$16*E31/SUM($E$25:$E$37),0)),$C$19)) | G31: ='ASESOR 07'!B7 | H31: ='ASESOR 07'!P3 | I31: ='ASESOR 07'!P4 | J31: ='ASESOR 07'!P5 | K31: ='ASESOR 07'!P6 | L31: ='ASESOR 07'!P7 | M31: ='ASESOR 07'!Z3 | N31: ='ASESOR 07'!Z4 | O31: ='ASESOR 07'!Z5 | P31: ='ASESOR 07'!Z6
B32: =IF('ASESOR 08'!B3="","",'ASESOR 08'!B3) | C32: =IF('ASESOR 08'!B4="","",'ASESOR 08'!B4) | D32: =IF('ASESOR 08'!B5="","",'ASESOR 08'!B5) | F32: =IF(OR(B32="",$C$16=""),"",IF(SUM($E$25:$E$37)>0,MAX($C$18,ROUND($C$16*E32/SUM($E$25:$E$37),0)),$C$19)) | G32: ='ASESOR 08'!B7 | H32: ='ASESOR 08'!P3 | I32: ='ASESOR 08'!P4 | J32: ='ASESOR 08'!P5 | K32: ='ASESOR 08'!P6 | L32: ='ASESOR 08'!P7 | M32: ='ASESOR 08'!Z3 | N32: ='ASESOR 08'!Z4 | O32: ='ASESOR 08'!Z5 | P32: ='ASESOR 08'!Z6
B33: =IF('ASESOR 09'!B3="","",'ASESOR 09'!B3) | C33: =IF('ASESOR 09'!B4="","",'ASESOR 09'!B4) | D33: =IF('ASESOR 09'!B5="","",'ASESOR 09'!B5) | F33: =IF(OR(B33="",$C$16=""),"",IF(SUM($E$25:$E$37)>0,MAX($C$18,ROUND($C$16*E33/SUM($E$25:$E$37),0)),$C$19)) | G33: ='ASESOR 09'!B7 | H33: ='ASESOR 09'!P3 | I33: ='ASESOR 09'!P4 | J33: ='ASESOR 09'!P5 | K33: ='ASESOR 09'!P6 | L33: ='ASESOR 09'!P7 | M33: ='ASESOR 09'!Z3 | N33: ='ASESOR 09'!Z4 | O33: ='ASESOR 09'!Z5 | P33: ='ASESOR 09'!Z6
B34: =IF('ASESOR 10'!B3="","",'ASESOR 10'!B3) | C34: =IF('ASESOR 10'!B4="","",'ASESOR 10'!B4) | D34: =IF('ASESOR 10'!B5="","",'ASESOR 10'!B5) | F34: =IF(OR(B34="",$C$16=""),"",IF(SUM($E$25:$E$37)>0,MAX($C$18,ROUND($C$16*E34/SUM($E$25:$E$37),0)),$C$19)) | G34: ='ASESOR 10'!B7 | H34: ='ASESOR 10'!P3 | I34: ='ASESOR 10'!P4 | J34: ='ASESOR 10'!P5 | K34: ='ASESOR 10'!P6 | L34: ='ASESOR 10'!P7 | M34: ='ASESOR 10'!Z3 | N34: ='ASESOR 10'!Z4 | O34: ='ASESOR 10'!Z5 | P34: ='ASESOR 10'!Z6
B35: =IF('ASESOR 11'!B3="","",'ASESOR 11'!B3) | C35: =IF('ASESOR 11'!B4="","",'ASESOR 11'!B4) | D35: =IF('ASESOR 11'!B5="","",'ASESOR 11'!B5) | F35: =IF(OR(B35="",$C$16=""),"",IF(SUM($E$25:$E$37)>0,MAX($C$18,ROUND($C$16*E35/SUM($E$25:$E$37),0)),$C$19)) | G35: ='ASESOR 11'!B7 | H35: ='ASESOR 11'!P3 | I35: ='ASESOR 11'!P4 | J35: ='ASESOR 11'!P5 | K35: ='ASESOR 11'!P6 | L35: ='ASESOR 11'!P7 | M35: ='ASESOR 11'!Z3 | N35: ='ASESOR 11'!Z4 | O35: ='ASESOR 11'!Z5 | P35: ='ASESOR 11'!Z6
B36: =IF('ASESOR 12'!B3="","",'ASESOR 12'!B3) | C36: =IF('ASESOR 12'!B4="","",'ASESOR 12'!B4) | D36: =IF('ASESOR 12'!B5="","",'ASESOR 12'!B5) | F36: =IF(OR(B36="",$C$16=""),"",IF(SUM($E$25:$E$37)>0,MAX($C$18,ROUND($C$16*E36/SUM($E$25:$E$37),0)),$C$19)) | G36: ='ASESOR 12'!B7 | H36: ='ASESOR 12'!P3 | I36: ='ASESOR 12'!P4 | J36: ='ASESOR 12'!P5 | K36: ='ASESOR 12'!P6 | L36: ='ASESOR 12'!P7 | M36: ='ASESOR 12'!Z3 | N36: ='ASESOR 12'!Z4 | O36: ='ASESOR 12'!Z5 | P36: ='ASESOR 12'!Z6
B37: =IF('ASESOR 13'!B3="","",'ASESOR 13'!B3) | C37: =IF('ASESOR 13'!B4="","",'ASESOR 13'!B4) | D37: =IF('ASESOR 13'!B5="","",'ASESOR 13'!B5) | F37: =IF(OR(B37="",$C$16=""),"",IF(SUM($E$25:$E$37)>0,MAX($C$18,ROUND($C$16*E37/SUM($E$25:$E$37),0)),$C$19)) | G37: ='ASESOR 13'!B7 | H37: ='ASESOR 13'!P3 | I37: ='ASESOR 13'!P4 | J37: ='ASESOR 13'!P5 | K37: ='ASESOR 13'!P6 | L37: ='ASESOR 13'!P7 | M37: ='ASESOR 13'!Z3 | N37: ='ASESOR 13'!Z4 | O37: ='ASESOR 13'!Z5 | P37: ='ASESOR 13'!Z6

Sheet ASESOR 01
A1: FORMATO DE MONITOREO COMERCIAL · PREVENTA Y VENTA
A3: Asesor | I3: Fase I (Habeas Data) | P3: =IF($B$7=0,"",IF(SUM(I74,L74,O74,R74,U74,X74)>0,"Reprobada","Aprobada")) | S3: ECU · % sin error | Z3: =IF($B$7=0,"",1-SUM(I75,L75,O75,R75,U75,X75)/$B$7)
A4: Canal | I4: Nota /100 | P4: =IF($B$7=0,"",IF(P3="Reprobada",0,AVERAGE(K73,N73,Q73,T73,W73,Z73)*1)) | S4: ECN · % sin error | Z4: =IF($B$7=0,"",1-SUM(I76,L76,O76,R76,U76,X76)/$B$7)
A5: Gestión | I5: Nota /300 | P5: =IF(P4="","",P4*3) | S5: ECC · % sin error | Z5: =IF($B$7=0,"",1-SUM(I77,L77,O77,R77,U77,X77)/$B$7)
A6: Mes | I6: Nivel | P6: =IF(P4="","",IF(P3="Reprobada","Crítico",LOOKUP(P4/100,'TABLA GENERAL'!$I$7:$I$10,'TABLA GENERAL'!$F$7:$F$10))) | S6: Alerta Dirección | Z6: =IF($B$7=0,"",IF(SUMPRODUCT($AD$14:$AD$71*((I14:I71="NO")+(L14:L71="NO")+(O14:O71="NO")+(R14:R71="NO")+(U14:U71="NO")+(X14:X71="NO")))>0,"SÍ - reportar","No"))
A7: Conversaciones evaluadas | B7: =SUM(I78,L78,O78,R78,U78,X78) | I7: Estado | P7: =IF(P4="","",IF(P3="Reprobada","Reprobado",IF(P4/100>='TABLA GENERAL'!$C$21,"Aprobado","Plan de acción"))) | S7: Casillas por revisar | Z7: =SUM(I79,L79,O79,R79,U79,X79)+COUNTIF(AE14:AE71,"REVISAR")
I9: Conversación 1 | L9: Conversación 2 | O9: Conversación 3 | R9: Conversación 4 | U9: Conversación 5 | X9: Conversación 6
C10: Fecha / ID de la conversación
C11: Modalidad
A13: Código | B13: Dimensión | C13: Descripción | D13: Tipo | E13: Aplica | F13: Peso base | G13: Receptor N/A | H13: Admite N/A | I13: Resultado | J13: Peso estab. | K13: Peso logrado | L13: Resultado | M13: Peso estab. | N13: Peso logrado | O13: Resultado | P13: Peso estab. | Q13: Peso logrado | R13: Resultado | S13: Peso estab. | T13: Peso logrado | U13: Resultado | V13: Peso estab. | W13: Peso logrado | X13: Resultado | Y13: Peso estab. | Z13: Peso logrado | AA13: Σ peso estab. | AB13: Σ peso logrado | AC13: % cumplimiento | AD13: Alerta | AE13: Validación
A14: =CRITERIOS!B2 | B14: =CRITERIOS!C2 | C14: =CRITERIOS!D2 | D14: =CRITERIOS!E2 | E14: =IFERROR(IF(AND(OR(CRITERIOS!F2="Todos",CRITERIOS!F2=$B$4),INDEX(CRITERIOS!H2:J2,MATCH($B$5,VARIABLES!$E$2:$E$4,0))=1),1,0),0) | F14: =IFERROR(IF(E14=1,INDEX(CRITERIOS!K2:M2,MATCH($B$5,VARIABLES!$E$2:$E$4,0)),0),0) | G14: =IF(CRITERIOS!N2="","",CRITERIOS!N2) | H14: =IF(CRITERIOS!O2="","",CRITERIOS!O2) | J14: =IF(OR($E14=0,I$78=0),0,IF(AND(I14="N/A",$G14<>""),0,$F14+SUMPRODUCT(($G$14:$G$71=$A14)*($E$14:$E$71=1)*(I$14:I$71="N/A")*$F$14:$F$71))) | K14: =IF(I14="SI",J14,0) | M14: =IF(OR($E14=0,L$78=0),0,IF(AND(L14="N/A",$G14<>""),0,$F14+SUMPRODUCT(($G$14:$G$71=$A14)*($E$14:$E$71=1)*(L$14:L$71="N/A")*$F$14:$F$71))) | N14: =IF(L14="SI",M14,0) | P14: =IF(OR($E14=0,O$78=0),0,IF(AND(O14="N/A",$G14<>""),0,$F14+SUMPRODUCT(($G$14:$G$71=$A14)*($E$14:$E$71=1)*(O$14:O$71="N/A")*$F$14:$F$71))) | Q14: =IF(O14="SI",P14,0) | S14: =IF(OR($E14=0,R$78=0),0,IF(AND(R14="N/A",$G14<>""),0,$F14+SUMPRODUCT(($G$14:$G$71=$A14)*($E$14:$E$71=1)*(R$14:R$71="N/A")*$F$14:$F$71))) | T14: =IF(R14="SI",S14,0) | V14: =IF(OR($E14=0,U$78=0),0,IF(AND(U14="N/A",$G14<>""),0,$F14+SUMPRODUCT(($G$14:$G$71=$A14)*($E$14:$E$71=1)*(U$14:U$71="N/A")*$F$14:$F$71))) | W14: =IF(U14="SI",V14,0) | Y14: =IF(OR($E14=0,X$78=0),0,IF(AND(X14="N/A",$G14<>""),0,$F14+SUMPRODUCT(($G$14:$G$71=$A14)*($E$14:$E$71=1)*(X$14:X$71="N/A")*$F$14:$F$71))) | Z14: =IF(X14="SI",Y14,0) | AA14: =SUM(J14,M14,P14,S14,V14,Y14) | AB14: =SUM(K14,N14,Q14,T14,W14,Z14) | AC14: =IF(AA14=0,"",AB14/AA14) | AD14: =CRITERIOS!Q2 | AE14: =IF(AND(E14=1,H14<>"X",((I14="N/A")+(L14="N/A")+(O14="N/A")+(R14="N/A")+(U14="N/A")+(X14="N/A"))>0),"REVISAR","")
A15: =CRITERIOS!B3 | B15: =CRITERIOS!C3 | C15: =CRITERIOS!D3 | D15: =CRITERIOS!E3 | E15: =IFERROR(IF(AND(OR(CRITERIOS!F3="Todos",CRITERIOS!F3=$B$4),INDEX(CRITERIOS!H3:J3,MATCH($B$5,VARIABLES!$E$2:$E$4,0))=1),1,0),0) | F15: =IFERROR(IF(E15=1,INDEX(CRITERIOS!K3:M3,MATCH($B$5,VARIABLES!$E$2:$E$4,0)),0),0) | G15: =IF(CRITERIOS!N3="","",CRITERIOS!N3) | H15: =IF(CRITERIOS!O3="","",CRITERIOS!O3) | J15: =IF(OR($E15=0,I$78=0),0,IF(AND(I15="N/A",$G15<>""),0,$F15+SUMPRODUCT(($G$14:$G$71=$A15)*($E$14:$E$71=1)*(I$14:I$71="N/A")*$F$14:$F$71))) | K15: =IF(I15="SI",J15,0) | M15: =IF(OR($E15=0,L$78=0),0,IF(AND(L15="N/A",$G15<>""),0,$F15+SUMPRODUCT(($G$14:$G$71=$A15)*($E$14:$E$71=1)*(L$14:L$71="N/A")*$F$14:$F$71))) | N15: =IF(L15="SI",M15,0) | P15: =IF(OR($E15=0,O$78=0),0,IF(AND(O15="N/A",$G15<>""),0,$F15+SUMPRODUCT(($G$14:$G$71=$A15)*($E$14:$E$71=1)*(O$14:O$71="N/A")*$F$14:$F$71))) | Q15: =IF(O15="SI",P15,0) | S15: =IF(OR($E15=0,R$78=0),0,IF(AND(R15="N/A",$G15<>""),0,$F15+SUMPRODUCT(($G$14:$G$71=$A15)*($E$14:$E$71=1)*(R$14:R$71="N/A")*$F$14:$F$71))) | T15: =IF(R15="SI",S15,0) | V15: =IF(OR($E15=0,U$78=0),0,IF(AND(U15="N/A",$G15<>""),0,$F15+SUMPRODUCT(($G$14:$G$71=$A15)*($E$14:$E$71=1)*(U$14:U$71="N/A")*$F$14:$F$71))) | W15: =IF(U15="SI",V15,0) | Y15: =IF(OR($E15=0,X$78=0),0,IF(AND(X15="N/A",$G15<>""),0,$F15+SUMPRODUCT(($G$14:$G$71=$A15)*($E$14:$E$71=1)*(X$14:X$71="N/A")*$F$14:$F$71))) | Z15: =IF(X15="SI",Y15,0) | AA15: =SUM(J15,M15,P15,S15,V15,Y15) | AB15: =SUM(K15,N15,Q15,T15,W15,Z15) | AC15: =IF(AA15=0,"",AB15/AA15) | AD15: =CRITERIOS!Q3 | AE15: =IF(AND(E15=1,H15<>"X",((I15="N/A")+(L15="N/A")+(O15="N/A")+(R15="N/A")+(U15="N/A")+(X15="N/A"))>0),"REVISAR","")
A16: =CRITERIOS!B4 | B16: =CRITERIOS!C4 | C16: =CRITERIOS!D4 | D16: =CRITERIOS!E4 | E16: =IFERROR(IF(AND(OR(CRITERIOS!F4="Todos",CRITERIOS!F4=$B$4),INDEX(CRITERIOS!H4:J4,MATCH($B$5,VARIABLES!$E$2:$E$4,0))=1),1,0),0) | F16: =IFERROR(IF(E16=1,INDEX(CRITERIOS!K4:M4,MATCH($B$5,VARIABLES!$E$2:$E$4,0)),0),0) | G16: =IF(CRITERIOS!N4="","",CRITERIOS!N4) | H16: =IF(CRITERIOS!O4="","",CRITERIOS!O4) | J16: =IF(OR($E16=0,I$78=0),0,IF(AND(I16="N/A",$G16<>""),0,$F16+SUMPRODUCT(($G$14:$G$71=$A16)*($E$14:$E$71=1)*(I$14:I$71="N/A")*$F$14:$F$71))) | K16: =IF(I16="SI",J16,0) | M16: =IF(OR($E16=0,L$78=0),0,IF(AND(L16="N/A",$G16<>""),0,$F16+SUMPRODUCT(($G$14:$G$71=$A16)*($E$14:$E$71=1)*(L$14:L$71="N/A")*$F$14:$F$71))) | N16: =IF(L16="SI",M16,0) | P16: =IF(OR($E16=0,O$78=0),0,IF(AND(O16="N/A",$G16<>""),0,$F16+SUMPRODUCT(($G$14:$G$71=$A16)*($E$14:$E$71=1)*(O$14:O$71="N/A")*$F$14:$F$71))) | Q16: =IF(O16="SI",P16,0) | S16: =IF(OR($E16=0,R$78=0),0,IF(AND(R16="N/A",$G16<>""),0,$F16+SUMPRODUCT(($G$14:$G$71=$A16)*($E$14:$E$71=1)*(R$14:R$71="N/A")*$F$14:$F$71))) | T16: =IF(R16="SI",S16,0) | V16: =IF(OR($E16=0,U$78=0),0,IF(AND(U16="N/A",$G16<>""),0,$F16+SUMPRODUCT(($G$14:$G$71=$A16)*($E$14:$E$71=1)*(U$14:U$71="N/A")*$F$14:$F$71))) | W16: =IF(U16="SI",V16,0) | Y16: =IF(OR($E16=0,X$78=0),0,IF(AND(X16="N/A",$G16<>""),0,$F16+SUMPRODUCT(($G$14:$G$71=$A16)*($E$14:$E$71=1)*(X$14:X$71="N/A")*$F$14:$F$71))) | Z16: =IF(X16="SI",Y16,0) | AA16: =SUM(J16,M16,P16,S16,V16,Y16) | AB16: =SUM(K16,N16,Q16,T16,W16,Z16) | AC16: =IF(AA16=0,"",AB16/AA16) | AD16: =CRITERIOS!Q4 | AE16: =IF(AND(E16=1,H16<>"X",((I16="N/A")+(L16="N/A")+(O16="N/A")+(R16="N/A")+(U16="N/A")+(X16="N/A"))>0),"REVISAR","")
A17: =CRITERIOS!B5 | B17: =CRITERIOS!C5 | C17: =CRITERIOS!D5 | D17: =CRITERIOS!E5 | E17: =IFERROR(IF(AND(OR(CRITERIOS!F5="Todos",CRITERIOS!F5=$B$4),INDEX(CRITERIOS!H5:J5,MATCH($B$5,VARIABLES!$E$2:$E$4,0))=1),1,0),0) | F17: =IFERROR(IF(E17=1,INDEX(CRITERIOS!K5:M5,MATCH($B$5,VARIABLES!$E$2:$E$4,0)),0),0) | G17: =IF(CRITERIOS!N5="","",CRITERIOS!N5) | H17: =IF(CRITERIOS!O5="","",CRITERIOS!O5) | J17: =IF(OR($E17=0,I$78=0),0,IF(AND(I17="N/A",$G17<>""),0,$F17+SUMPRODUCT(($G$14:$G$71=$A17)*($E$14:$E$71=1)*(I$14:I$71="N/A")*$F$14:$F$71))) | K17: =IF(I17="SI",J17,0) | M17: =IF(OR($E17=0,L$78=0),0,IF(AND(L17="N/A",$G17<>""),0,$F17+SUMPRODUCT(($G$14:$G$71=$A17)*($E$14:$E$71=1)*(L$14:L$71="N/A")*$F$14:$F$71))) | N17: =IF(L17="SI",M17,0) | P17: =IF(OR($E17=0,O$78=0),0,IF(AND(O17="N/A",$G17<>""),0,$F17+SUMPRODUCT(($G$14:$G$71=$A17)*($E$14:$E$71=1)*(O$14:O$71="N/A")*$F$14:$F$71))) | Q17: =IF(O17="SI",P17,0) | S17: =IF(OR($E17=0,R$78=0),0,IF(AND(R17="N/A",$G17<>""),0,$F17+SUMPRODUCT(($G$14:$G$71=$A17)*($E$14:$E$71=1)*(R$14:R$71="N/A")*$F$14:$F$71))) | T17: =IF(R17="SI",S17,0) | V17: =IF(OR($E17=0,U$78=0),0,IF(AND(U17="N/A",$G17<>""),0,$F17+SUMPRODUCT(($G$14:$G$71=$A17)*($E$14:$E$71=1)*(U$14:U$71="N/A")*$F$14:$F$71))) | W17: =IF(U17="SI",V17,0) | Y17: =IF(OR($E17=0,X$78=0),0,IF(AND(X17="N/A",$G17<>""),0,$F17+SUMPRODUCT(($G$14:$G$71=$A17)*($E$14:$E$71=1)*(X$14:X$71="N/A")*$F$14:$F$71))) | Z17: =IF(X17="SI",Y17,0) | AA17: =SUM(J17,M17,P17,S17,V17,Y17) | AB17: =SUM(K17,N17,Q17,T17,W17,Z17) | AC17: =IF(AA17=0,"",AB17/AA17) | AD17: =CRITERIOS!Q5 | AE17: =IF(AND(E17=1,H17<>"X",((I17="N/A")+(L17="N/A")+(O17="N/A")+(R17="N/A")+(U17="N/A")+(X17="N/A"))>0),"REVISAR","")
A18: =CRITERIOS!B6 | B18: =CRITERIOS!C6 | C18: =CRITERIOS!D6 | D18: =CRITERIOS!E6 | E18: =IFERROR(IF(AND(OR(CRITERIOS!F6="Todos",CRITERIOS!F6=$B$4),INDEX(CRITERIOS!H6:J6,MATCH($B$5,VARIABLES!$E$2:$E$4,0))=1),1,0),0) | F18: =IFERROR(IF(E18=1,INDEX(CRITERIOS!K6:M6,MATCH($B$5,VARIABLES!$E$2:$E$4,0)),0),0) | G18: =IF(CRITERIOS!N6="","",CRITERIOS!N6) | H18: =IF(CRITERIOS!O6="","",CRITERIOS!O6) | J18: =IF(OR($E18=0,I$78=0),0,IF(AND(I18="N/A",$G18<>""),0,$F18+SUMPRODUCT(($G$14:$G$71=$A18)*($E$14:$E$71=1)*(I$14:I$71="N/A")*$F$14:$F$71))) | K18: =IF(I18="SI",J18,0) | M18: =IF(OR($E18=0,L$78=0),0,IF(AND(L18="N/A",$G18<>""),0,$F18+SUMPRODUCT(($G$14:$G$71=$A18)*($E$14:$E$71=1)*(L$14:L$71="N/A")*$F$14:$F$71))) | N18: =IF(L18="SI",M18,0) | P18: =IF(OR($E18=0,O$78=0),0,IF(AND(O18="N/A",$G18<>""),0,$F18+SUMPRODUCT(($G$14:$G$71=$A18)*($E$14:$E$71=1)*(O$14:O$71="N/A")*$F$14:$F$71))) | Q18: =IF(O18="SI",P18,0) | S18: =IF(OR($E18=0,R$78=0),0,IF(AND(R18="N/A",$G18<>""),0,$F18+SUMPRODUCT(($G$14:$G$71=$A18)*($E$14:$E$71=1)*(R$14:R$71="N/A")*$F$14:$F$71))) | T18: =IF(R18="SI",S18,0) | V18: =IF(OR($E18=0,U$78=0),0,IF(AND(U18="N/A",$G18<>""),0,$F18+SUMPRODUCT(($G$14:$G$71=$A18)*($E$14:$E$71=1)*(U$14:U$71="N/A")*$F$14:$F$71))) | W18: =IF(U18="SI",V18,0) | Y18: =IF(OR($E18=0,X$78=0),0,IF(AND(X18="N/A",$G18<>""),0,$F18+SUMPRODUCT(($G$14:$G$71=$A18)*($E$14:$E$71=1)*(X$14:X$71="N/A")*$F$14:$F$71))) | Z18: =IF(X18="SI",Y18,0) | AA18: =SUM(J18,M18,P18,S18,V18,Y18) | AB18: =SUM(K18,N18,Q18,T18,W18,Z18) | AC18: =IF(AA18=0,"",AB18/AA18) | AD18: =CRITERIOS!Q6 | AE18: =IF(AND(E18=1,H18<>"X",((I18="N/A")+(L18="N/A")+(O18="N/A")+(R18="N/A")+(U18="N/A")+(X18="N/A"))>0),"REVISAR","")
A19: =CRITERIOS!B7 | B19: =CRITERIOS!C7 | C19: =CRITERIOS!D7 | D19: =CRITERIOS!E7 | E19: =IFERROR(IF(AND(OR(CRITERIOS!F7="Todos",CRITERIOS!F7=$B$4),INDEX(CRITERIOS!H7:J7,MATCH($B$5,VARIABLES!$E$2:$E$4,0))=1),1,0),0) | F19: =IFERROR(IF(E19=1,INDEX(CRITERIOS!K7:M7,MATCH($B$5,VARIABLES!$E$2:$E$4,0)),0),0) | G19: =IF(CRITERIOS!N7="","",CRITERIOS!N7) | H19: =IF(CRITERIOS!O7="","",CRITERIOS!O7) | J19: =IF(OR($E19=0,I$78=0),0,IF(AND(I19="N/A",$G19<>""),0,$F19+SUMPRODUCT(($G$14:$G$71=$A19)*($E$14:$E$71=1)*(I$14:I$71="N/A")*$F$14:$F$71))) | K19: =IF(I19="SI",J19,0) | M19: =IF(OR($E19=0,L$78=0),0,IF(AND(L19="N/A",$G19<>""),0,$F19+SUMPRODUCT(($G$14:$G$71=$A19)*($E$14:$E$71=1)*(L$14:L$71="N/A")*$F$14:$F$71))) | N19: =IF(L19="SI",M19,0) | P19: =IF(OR($E19=0,O$78=0),0,IF(AND(O19="N/A",$G19<>""),0,$F19+SUMPRODUCT(($G$14:$G$71=$A19)*($E$14:$E$71=1)*(O$14:O$71="N/A")*$F$14:$F$71))) | Q19: =IF(O19="SI",P19,0) | S19: =IF(OR($E19=0,R$78=0),0,IF(AND(R19="N/A",$G19<>""),0,$F19+SUMPRODUCT(($G$14:$G$71=$A19)*($E$14:$E$71=1)*(R$14:R$71="N/A")*$F$14:$F$71))) | T19: =IF(R19="SI",S19,0) | V19: =IF(OR($E19=0,U$78=0),0,IF(AND(U19="N/A",$G19<>""),0,$F19+SUMPRODUCT(($G$14:$G$71=$A19)*($E$14:$E$71=1)*(U$14:U$71="N/A")*$F$14:$F$71))) | W19: =IF(U19="SI",V19,0) | Y19: =IF(OR($E19=0,X$78=0),0,IF(AND(X19="N/A",$G19<>""),0,$F19+SUMPRODUCT(($G$14:$G$71=$A19)*($E$14:$E$71=1)*(X$14:X$71="N/A")*$F$14:$F$71))) | Z19: =IF(X19="SI",Y19,0) | AA19: =SUM(J19,M19,P19,S19,V19,Y19) | AB19: =SUM(K19,N19,Q19,T19,W19,Z19) | AC19: =IF(AA19=0,"",AB19/AA19) | AD19: =CRITERIOS!Q7 | AE19: =IF(AND(E19=1,H19<>"X",((I19="N/A")+(L19="N/A")+(O19="N/A")+(R19="N/A")+(U19="N/A")+(X19="N/A"))>0),"REVISAR","")
A20: =CRITERIOS!B8 | B20: =CRITERIOS!C8 | C20: =CRITERIOS!D8 | D20: =CRITERIOS!E8 | E20: =IFERROR(IF(AND(OR(CRITERIOS!F8="Todos",CRITERIOS!F8=$B$4),INDEX(CRITERIOS!H8:J8,MATCH($B$5,VARIABLES!$E$2:$E$4,0))=1),1,0),0) | F20: =IFERROR(IF(E20=1,INDEX(CRITERIOS!K8:M8,MATCH($B$5,VARIABLES!$E$2:$E$4,0)),0),0) | G20: =IF(CRITERIOS!N8="","",CRITERIOS!N8) | H20: =IF(CRITERIOS!O8="","",CRITERIOS!O8) | J20: =IF(OR($E20=0,I$78=0),0,IF(AND(I20="N/A",$G20<>""),0,$F20+SUMPRODUCT(($G$14:$G$71=$A20)*($E$14:$E$71=1)*(I$14:I$71="N/A")*$F$14:$F$71))) | K20: =IF(I20="SI",J20,0) | M20: =IF(OR($E20=0,L$78=0),0,IF(AND(L20="N/A",$G20<>""),0,$F20+SUMPRODUCT(($G$14:$G$71=$A20)*($E$14:$E$71=1)*(L$14:L$71="N/A")*$F$14:$F$71))) | N20: =IF(L20="SI",M20,0) | P20: =IF(OR($E20=0,O$78=0),0,IF(AND(O20="N/A",$G20<>""),0,$F20+SUMPRODUCT(($G$14:$G$71=$A20)*($E$14:$E$71=1)*(O$14:O$71="N/A")*$F$14:$F$71))) | Q20: =IF(O20="SI",P20,0) | S20: =IF(OR($E20=0,R$78=0),0,IF(AND(R20="N/A",$G20<>""),0,$F20+SUMPRODUCT(($G$14:$G$71=$A20)*($E$14:$E$71=1)*(R$14:R$71="N/A")*$F$14:$F$71))) | T20: =IF(R20="SI",S20,0) | V20: =IF(OR($E20=0,U$78=0),0,IF(AND(U20="N/A",$G20<>""),0,$F20+SUMPRODUCT(($G$14:$G$71=$A20)*($E$14:$E$71=1)*(U$14:U$71="N/A")*$F$14:$F$71))) | W20: =IF(U20="SI",V20,0) | Y20: =IF(OR($E20=0,X$78=0),0,IF(AND(X20="N/A",$G20<>""),0,$F20+SUMPRODUCT(($G$14:$G$71=$A20)*($E$14:$E$71=1)*(X$14:X$71="N/A")*$F$14:$F$71))) | Z20: =IF(X20="SI",Y20,0) | AA20: =SUM(J20,M20,P20,S20,V20,Y20) | AB20: =SUM(K20,N20,Q20,T20,W20,Z20) | AC20: =IF(AA20=0,"",AB20/AA20) | AD20: =CRITERIOS!Q8 | AE20: =IF(AND(E20=1,H20<>"X",((I20="N/A")+(L20="N/A")+(O20="N/A")+(R20="N/A")+(U20="N/A")+(X20="N/A"))>0),"REVISAR","")
A21: =CRITERIOS!B9 | B21: =CRITERIOS!C9 | C21: =CRITERIOS!D9 | D21: =CRITERIOS!E9 | E21: =IFERROR(IF(AND(OR(CRITERIOS!F9="Todos",CRITERIOS!F9=$B$4),INDEX(CRITERIOS!H9:J9,MATCH($B$5,VARIABLES!$E$2:$E$4,0))=1),1,0),0) | F21: =IFERROR(IF(E21=1,INDEX(CRITERIOS!K9:M9,MATCH($B$5,VARIABLES!$E$2:$E$4,0)),0),0) | G21: =IF(CRITERIOS!N9="","",CRITERIOS!N9) | H21: =IF(CRITERIOS!O9="","",CRITERIOS!O9) | J21: =IF(OR($E21=0,I$78=0),0,IF(AND(I21="N/A",$G21<>""),0,$F21+SUMPRODUCT(($G$14:$G$71=$A21)*($E$14:$E$71=1)*(I$14:I$71="N/A")*$F$14:$F$71))) | K21: =IF(I21="SI",J21,0) | M21: =IF(OR($E21=0,L$78=0),0,IF(AND(L21="N/A",$G21<>""),0,$F21+SUMPRODUCT(($G$14:$G$71=$A21)*($E$14:$E$71=1)*(L$14:L$71="N/A")*$F$14:$F$71))) | N21: =IF(L21="SI",M21,0) | P21: =IF(OR($E21=0,O$78=0),0,IF(AND(O21="N/A",$G21<>""),0,$F21+SUMPRODUCT(($G$14:$G$71=$A21)*($E$14:$E$71=1)*(O$14:O$71="N/A")*$F$14:$F$71))) | Q21: =IF(O21="SI",P21,0) | S21: =IF(OR($E21=0,R$78=0),0,IF(AND(R21="N/A",$G21<>""),0,$F21+SUMPRODUCT(($G$14:$G$71=$A21)*($E$14:$E$71=1)*(R$14:R$71="N/A")*$F$14:$F$71))) | T21: =IF(R21="SI",S21,0) | V21: =IF(OR($E21=0,U$78=0),0,IF(AND(U21="N/A",$G21<>""),0,$F21+SUMPRODUCT(($G$14:$G$71=$A21)*($E$14:$E$71=1)*(U$14:U$71="N/A")*$F$14:$F$71))) | W21: =IF(U21="SI",V21,0) | Y21: =IF(OR($E21=0,X$78=0),0,IF(AND(X21="N/A",$G21<>""),0,$F21+SUMPRODUCT(($G$14:$G$71=$A21)*($E$14:$E$71=1)*(X$14:X$71="N/A")*$F$14:$F$71))) | Z21: =IF(X21="SI",Y21,0) | AA21: =SUM(J21,M21,P21,S21,V21,Y21) | AB21: =SUM(K21,N21,Q21,T21,W21,Z21) | AC21: =IF(AA21=0,"",AB21/AA21) | AD21: =CRITERIOS!Q9 | AE21: =IF(AND(E21=1,H21<>"X",((I21="N/A")+(L21="N/A")+(O21="N/A")+(R21="N/A")+(U21="N/A")+(X21="N/A"))>0),"REVISAR","")
A22: =CRITERIOS!B10 | B22: =CRITERIOS!C10 | C22: =CRITERIOS!D10 | D22: =CRITERIOS!E10 | E22: =IFERROR(IF(AND(OR(CRITERIOS!F10="Todos",CRITERIOS!F10=$B$4),INDEX(CRITERIOS!H10:J10,MATCH($B$5,VARIABLES!$E$2:$E$4,0))=1),1,0),0) | F22: =IFERROR(IF(E22=1,INDEX(CRITERIOS!K10:M10,MATCH($B$5,VARIABLES!$E$2:$E$4,0)),0),0) | G22: =IF(CRITERIOS!N10="","",CRITERIOS!N10) | H22: =IF(CRITERIOS!O10="","",CRITERIOS!O10) | J22: =IF(OR($E22=0,I$78=0),0,IF(AND(I22="N/A",$G22<>""),0,$F22+SUMPRODUCT(($G$14:$G$71=$A22)*($E$14:$E$71=1)*(I$14:I$71="N/A")*$F$14:$F$71))) | K22: =IF(I22="SI",J22,0) | M22: =IF(OR($E22=0,L$78=0),0,IF(AND(L22="N/A",$G22<>""),0,$F22+SUMPRODUCT(($G$14:$G$71=$A22)*($E$14:$E$71=1)*(L$14:L$71="N/A")*$F$14:$F$71))) | N22: =IF(L22="SI",M22,0) | P22: =IF(OR($E22=0,O$78=0),0,IF(AND(O22="N/A",$G22<>""),0,$F22+SUMPRODUCT(($G$14:$G$71=$A22)*($E$14:$E$71=1)*(O$14:O$71="N/A")*$F$14:$F$71))) | Q22: =IF(O22="SI",P22,0) | S22: =IF(OR($E22=0,R$78=0),0,IF(AND(R22="N/A",$G22<>""),0,$F22+SUMPRODUCT(($G$14:$G$71=$A22)*($E$14:$E$71=1)*(R$14:R$71="N/A")*$F$14:$F$71))) | T22: =IF(R22="SI",S22,0) | V22: =IF(OR($E22=0,U$78=0),0,IF(AND(U22="N/A",$G22<>""),0,$F22+SUMPRODUCT(($G$14:$G$71=$A22)*($E$14:$E$71=1)*(U$14:U$71="N/A")*$F$14:$F$71))) | W22: =IF(U22="SI",V22,0) | Y22: =IF(OR($E22=0,X$78=0),0,IF(AND(X22="N/A",$G22<>""),0,$F22+SUMPRODUCT(($G$14:$G$71=$A22)*($E$14:$E$71=1)*(X$14:X$71="N/A")*$F$14:$F$71))) | Z22: =IF(X22="SI",Y22,0) | AA22: =SUM(J22,M22,P22,S22,V22,Y22) | AB22: =SUM(K22,N22,Q22,T22,W22,Z22) | AC22: =IF(AA22=0,"",AB22/AA22) | AD22: =CRITERIOS!Q10 | AE22: =IF(AND(E22=1,H22<>"X",((I22="N/A")+(L22="N/A")+(O22="N/A")+(R22="N/A")+(U22="N/A")+(X22="N/A"))>0),"REVISAR","")
A23: =CRITERIOS!B11 | B23: =CRITERIOS!C11 | C23: =CRITERIOS!D11 | D23: =CRITERIOS!E11 | E23: =IFERROR(IF(AND(OR(CRITERIOS!F11="Todos",CRITERIOS!F11=$B$4),INDEX(CRITERIOS!H11:J11,MATCH($B$5,VARIABLES!$E$2:$E$4,0))=1),1,0),0) | F23: =IFERROR(IF(E23=1,INDEX(CRITERIOS!K11:M11,MATCH($B$5,VARIABLES!$E$2:$E$4,0)),0),0) | G23: =IF(CRITERIOS!N11="","",CRITERIOS!N11) | H23: =IF(CRITERIOS!O11="","",CRITERIOS!O11) | J23: =IF(OR($E23=0,I$78=0),0,IF(AND(I23="N/A",$G23<>""),0,$F23+SUMPRODUCT(($G$14:$G$71=$A23)*($E$14:$E$71=1)*(I$14:I$71="N/A")*$F$14:$F$71))) | K23: =IF(I23="SI",J23,0) | M23: =IF(OR($E23=0,L$78=0),0,IF(AND(L23="N/A",$G23<>""),0,$F23+SUMPRODUCT(($G$14:$G$71=$A23)*($E$14:$E$71=1)*(L$14:L$71="N/A")*$F$14:$F$71))) | N23: =IF(L23="SI",M23,0) | P23: =IF(OR($E23=0,O$78=0),0,IF(AND(O23="N/A",$G23<>""),0,$F23+SUMPRODUCT(($G$14:$G$71=$A23)*($E$14:$E$71=1)*(O$14:O$71="N/A")*$F$14:$F$71))) | Q23: =IF(O23="SI",P23,0) | S23: =IF(OR($E23=0,R$78=0),0,IF(AND(R23="N/A",$G23<>""),0,$F23+SUMPRODUCT(($G$14:$G$71=$A23)*($E$14:$E$71=1)*(R$14:R$71="N/A")*$F$14:$F$71))) | T23: =IF(R23="SI",S23,0) | V23: =IF(OR($E23=0,U$78=0),0,IF(AND(U23="N/A",$G23<>""),0,$F23+SUMPRODUCT(($G$14:$G$71=$A23)*($E$14:$E$71=1)*(U$14:U$71="N/A")*$F$14:$F$71))) | W23: =IF(U23="SI",V23,0) | Y23: =IF(OR($E23=0,X$78=0),0,IF(AND(X23="N/A",$G23<>""),0,$F23+SUMPRODUCT(($G$14:$G$71=$A23)*($E$14:$E$71=1)*(X$14:X$71="N/A")*$F$14:$F$71))) | Z23: =IF(X23="SI",Y23,0) | AA23: =SUM(J23,M23,P23,S23,V23,Y23) | AB23: =SUM(K23,N23,Q23,T23,W23,Z23) | AC23: =IF(AA23=0,"",AB23/AA23) | AD23: =CRITERIOS!Q11 | AE23: =IF(AND(E23=1,H23<>"X",((I23="N/A")+(L23="N/A")+(O23="N/A")+(R23="N/A")+(U23="N/A")+(X23="N/A"))>0),"REVISAR","")
A24: =CRITERIOS!B12 | B24: =CRITERIOS!C12 | C24: =CRITERIOS!D12 | D24: =CRITERIOS!E12 | E24: =IFERROR(IF(AND(OR(CRITERIOS!F12="Todos",CRITERIOS!F12=$B$4),INDEX(CRITERIOS!H12:J12,MATCH($B$5,VARIABLES!$E$2:$E$4,0))=1),1,0),0) | F24: =IFERROR(IF(E24=1,INDEX(CRITERIOS!K12:M12,MATCH($B$5,VARIABLES!$E$2:$E$4,0)),0),0) | G24: =IF(CRITERIOS!N12="","",CRITERIOS!N12) | H24: =IF(CRITERIOS!O12="","",CRITERIOS!O12) | J24: =IF(OR($E24=0,I$78=0),0,IF(AND(I24="N/A",$G24<>""),0,$F24+SUMPRODUCT(($G$14:$G$71=$A24)*($E$14:$E$71=1)*(I$14:I$71="N/A")*$F$14:$F$71))) | K24: =IF(I24="SI",J24,0) | M24: =IF(OR($E24=0,L$78=0),0,IF(AND(L24="N/A",$G24<>""),0,$F24+SUMPRODUCT(($G$14:$G$71=$A24)*($E$14:$E$71=1)*(L$14:L$71="N/A")*$F$14:$F$71))) | N24: =IF(L24="SI",M24,0) | P24: =IF(OR($E24=0,O$78=0),0,IF(AND(O24="N/A",$G24<>""),0,$F24+SUMPRODUCT(($G$14:$G$71=$A24)*($E$14:$E$71=1)*(O$14:O$71="N/A")*$F$14:$F$71))) | Q24: =IF(O24="SI",P24,0) | S24: =IF(OR($E24=0,R$78=0),0,IF(AND(R24="N/A",$G24<>""),0,$F24+SUMPRODUCT(($G$14:$G$71=$A24)*($E$14:$E$71=1)*(R$14:R$71="N/A")*$F$14:$F$71))) | T24: =IF(R24="SI",S24,0) | V24: =IF(OR($E24=0,U$78=0),0,IF(AND(U24="N/A",$G24<>""),0,$F24+SUMPRODUCT(($G$14:$G$71=$A24)*($E$14:$E$71=1)*(U$14:U$71="N/A")*$F$14:$F$71))) | W24: =IF(U24="SI",V24,0) | Y24: =IF(OR($E24=0,X$78=0),0,IF(AND(X24="N/A",$G24<>""),0,$F24+SUMPRODUCT(($G$14:$G$71=$A24)*($E$14:$E$71=1)*(X$14:X$71="N/A")*$F$14:$F$71))) | Z24: =IF(X24="SI",Y24,0) | AA24: =SUM(J24,M24,P24,S24,V24,Y24) | AB24: =SUM(K24,N24,Q24,T24,W24,Z24) | AC24: =IF(AA24=0,"",AB24/AA24) | AD24: =CRITERIOS!Q12 | AE24: =IF(AND(E24=1,H24<>"X",((I24="N/A")+(L24="N/A")+(O24="N/A")+(R24="N/A")+(U24="N/A")+(X24="N/A"))>0),"REVISAR","")
A25: =CRITERIOS!B13 | B25: =CRITERIOS!C13 | C25: =CRITERIOS!D13 | D25: =CRITERIOS!E13 | E25: =IFERROR(IF(AND(OR(CRITERIOS!F13="Todos",CRITERIOS!F13=$B$4),INDEX(CRITERIOS!H13:J13,MATCH($B$5,VARIABLES!$E$2:$E$4,0))=1),1,0),0) | F25: =IFERROR(IF(E25=1,INDEX(CRITERIOS!K13:M13,MATCH($B$5,VARIABLES!$E$2:$E$4,0)),0),0) | G25: =IF(CRITERIOS!N13="","",CRITERIOS!N13) | H25: =IF(CRITERIOS!O13="","",CRITERIOS!O13) | J25: =IF(OR($E25=0,I$78=0),0,IF(AND(I25="N/A",$G25<>""),0,$F25+SUMPRODUCT(($G$14:$G$71=$A25)*($E$14:$E$71=1)*(I$14:I$71="N/A")*$F$14:$F$71))) | K25: =IF(I25="SI",J25,0) | M25: =IF(OR($E25=0,L$78=0),0,IF(AND(L25="N/A",$G25<>""),0,$F25+SUMPRODUCT(($G$14:$G$71=$A25)*($E$14:$E$71=1)*(L$14:L$71="N/A")*$F$14:$F$71))) | N25: =IF(L25="SI",M25,0) | P25: =IF(OR($E25=0,O$78=0),0,IF(AND(O25="N/A",$G25<>""),0,$F25+SUMPRODUCT(($G$14:$G$71=$A25)*($E$14:$E$71=1)*(O$14:O$71="N/A")*$F$14:$F$71))) | Q25: =IF(O25="SI",P25,0) | S25: =IF(OR($E25=0,R$78=0),0,IF(AND(R25="N/A",$G25<>""),0,$F25+SUMPRODUCT(($G$14:$G$71=$A25)*($E$14:$E$71=1)*(R$14:R$71="N/A")*$F$14:$F$71))) | T25: =IF(R25="SI",S25,0) | V25: =IF(OR($E25=0,U$78=0),0,IF(AND(U25="N/A",$G25<>""),0,$F25+SUMPRODUCT(($G$14:$G$71=$A25)*($E$14:$E$71=1)*(U$14:U$71="N/A")*$F$14:$F$71))) | W25: =IF(U25="SI",V25,0) | Y25: =IF(OR($E25=0,X$78=0),0,IF(AND(X25="N/A",$G25<>""),0,$F25+SUMPRODUCT(($G$14:$G$71=$A25)*($E$14:$E$71=1)*(X$14:X$71="N/A")*$F$14:$F$71))) | Z25: =IF(X25="SI",Y25,0) | AA25: =SUM(J25,M25,P25,S25,V25,Y25) | AB25: =SUM(K25,N25,Q25,T25,W25,Z25) | AC25: =IF(AA25=0,"",AB25/AA25) | AD25: =CRITERIOS!Q13 | AE25: =IF(AND(E25=1,H25<>"X",((I25="N/A")+(L25="N/A")+(O25="N/A")+(R25="N/A")+(U25="N/A")+(X25="N/A"))>0),"REVISAR","")
... A71: =CRITERIOS!B59 | B71: =CRITERIOS!C59 | C71: =CRITERIOS!D59 | D71: =CRITERIOS!E59 | E71: =IFERROR(IF(AND(OR(CRITERIOS!F59="Todos",CRITERIOS!F59=$B$4),INDEX(CRITERIOS!H59:J59,MATCH($B$5,VARIABLES!$E$2:$E$4,0))=1),1,0),0) | F71: =IFERROR(IF(E71=1,INDEX(CRITERIOS!K59:M59,MATCH($B$5,VARIABLES!$E$2:$E$4,0)),0),0) | G71: =IF(CRITERIOS!N59="","",CRITERIOS!N59) | H71: =IF(CRITERIOS!O59="","",CRITERIOS!O59) | J71: =IF(OR($E71=0,I$78=0),0,IF(AND(I71="N/A",$G71<>""),0,$F71+SUMPRODUCT(($G$14:$G$71=$A71)*($E$14:$E$71=1)*(I$14:I$71="N/A")*$F$14:$F$71))) | K71: =IF(I71="SI",J71,0) | M71: =IF(OR($E71=0,L$78=0),0,IF(AND(L71="N/A",$G71<>""),0,$F71+SUMPRODUCT(($G$14:$G$71=$A71)*($E$14:$E$71=1)*(L$14:L$71="N/A")*$F$14:$F$71))) | N71: =IF(L71="SI",M71,0) | P71: =IF(OR($E71=0,O$78=0),0,IF(AND(O71="N/A",$G71<>""),0,$F71+SUMPRODUCT(($G$14:$G$71=$A71)*($E$14:$E$71=1)*(O$14:O$71="N/A")*$F$14:$F$71))) | Q71: =IF(O71="SI",P71,0) | S71: =IF(OR($E71=0,R$78=0),0,IF(AND(R71="N/A",$G71<>""),0,$F71+SUMPRODUCT(($G$14:$G$71=$A71)*($E$14:$E$71=1)*(R$14:R$71="N/A")*$F$14:$F$71))) | T71: =IF(R71="SI",S71,0) | V71: =IF(OR($E71=0,U$78=0),0,IF(AND(U71="N/A",$G71<>""),0,$F71+SUMPRODUCT(($G$14:$G$71=$A71)*($E$14:$E$71=1)*(U$14:U$71="N/A")*$F$14:$F$71))) | W71: =IF(U71="SI",V71,0) | Y71: =IF(OR($E71=0,X$78=0),0,IF(AND(X71="N/A",$G71<>""),0,$F71+SUMPRODUCT(($G$14:$G$71=$A71)*($E$14:$E$71=1)*(X$14:X$71="N/A")*$F$14:$F$71))) | Z71: =IF(X71="SI",Y71,0) | AA71: =SUM(J71,M71,P71,S71,V71,Y71) | AB71: =SUM(K71,N71,Q71,T71,W71,Z71) | AC71: =IF(AA71=0,"",AB71/AA71) | AD71: =CRITERIOS!Q59 | AE71: =IF(AND(E71=1,H71<>"X",((I71="N/A")+(L71="N/A")+(O71="N/A")+(R71="N/A")+(U71="N/A")+(X71="N/A"))>0),"REVISAR","")
C73: Puntaje de la conversación (/100) | K73: =IF(I78=1,SUM(K14:K71),"") | N73: =IF(L78=1,SUM(N14:N71),"") | Q73: =IF(O78=1,SUM(Q14:Q71),"") | T73: =IF(R78=1,SUM(T14:T71),"") | W73: =IF(U78=1,SUM(W14:W71),"") | Z73: =IF(X78=1,SUM(Z14:Z71),"")
C74: Fase I: HD con NO (1 = reprueba) | I74: =IF(I78=1,IF(COUNTIFS($D$14:$D$71,"Control HD",I14:I71,"NO")>0,1,0),0) | L74: =IF(L78=1,IF(COUNTIFS($D$14:$D$71,"Control HD",L14:L71,"NO")>0,1,0),0) | O74: =IF(O78=1,IF(COUNTIFS($D$14:$D$71,"Control HD",O14:O71,"NO")>0,1,0),0) | R74: =IF(R78=1,IF(COUNTIFS($D$14:$D$71,"Control HD",R14:R71,"NO")>0,1,0),0) | U74: =IF(U78=1,IF(COUNTIFS($D$14:$D$71,"Control HD",U14:U71,"NO")>0,1,0),0) | X74: =IF(X78=1,IF(COUNTIFS($D$14:$D$71,"Control HD",X14:X71,"NO")>0,1,0),0)
C75: ECU con error (1 = sí) | I75: =IF(I78=1,IF(COUNTIFS($D$14:$D$71,"ECU",I14:I71,"NO")>0,1,0),0) | L75: =IF(L78=1,IF(COUNTIFS($D$14:$D$71,"ECU",L14:L71,"NO")>0,1,0),0) | O75: =IF(O78=1,IF(COUNTIFS($D$14:$D$71,"ECU",O14:O71,"NO")>0,1,0),0) | R75: =IF(R78=1,IF(COUNTIFS($D$14:$D$71,"ECU",R14:R71,"NO")>0,1,0),0) | U75: =IF(U78=1,IF(COUNTIFS($D$14:$D$71,"ECU",U14:U71,"NO")>0,1,0),0) | X75: =IF(X78=1,IF(COUNTIFS($D$14:$D$71,"ECU",X14:X71,"NO")>0,1,0),0)
C76: ECN con error (1 = sí) | I76: =IF(I78=1,IF(COUNTIFS($D$14:$D$71,"ECN",I14:I71,"NO")>0,1,0),0) | L76: =IF(L78=1,IF(COUNTIFS($D$14:$D$71,"ECN",L14:L71,"NO")>0,1,0),0) | O76: =IF(O78=1,IF(COUNTIFS($D$14:$D$71,"ECN",O14:O71,"NO")>0,1,0),0) | R76: =IF(R78=1,IF(COUNTIFS($D$14:$D$71,"ECN",R14:R71,"NO")>0,1,0),0) | U76: =IF(U78=1,IF(COUNTIFS($D$14:$D$71,"ECN",U14:U71,"NO")>0,1,0),0) | X76: =IF(X78=1,IF(COUNTIFS($D$14:$D$71,"ECN",X14:X71,"NO")>0,1,0),0)
C77: ECC con error (1 = sí) | I77: =IF(I78=1,IF(COUNTIFS($D$14:$D$71,"ECC",I14:I71,"NO")>0,1,0),0) | L77: =IF(L78=1,IF(COUNTIFS($D$14:$D$71,"ECC",L14:L71,"NO")>0,1,0),0) | O77: =IF(O78=1,IF(COUNTIFS($D$14:$D$71,"ECC",O14:O71,"NO")>0,1,0),0) | R77: =IF(R78=1,IF(COUNTIFS($D$14:$D$71,"ECC",R14:R71,"NO")>0,1,0),0) | U77: =IF(U78=1,IF(COUNTIFS($D$14:$D$71,"ECC",U14:U71,"NO")>0,1,0),0) | X77: =IF(X78=1,IF(COUNTIFS($D$14:$D$71,"ECC",X14:X71,"NO")>0,1,0),0)
C78: Conversación evaluada (1 = sí) | I78: =IF(COUNTA(I14:I71)>0,1,0) | L78: =IF(COUNTA(L14:L71)>0,1,0) | O78: =IF(COUNTA(O14:O71)>0,1,0) | R78: =IF(COUNTA(R14:R71)>0,1,0) | U78: =IF(COUNTA(U14:U71)>0,1,0) | X78: =IF(COUNTA(X14:X71)>0,1,0)
C79: Casillas aplicables sin diligenciar | I79: =IF(I78=1,SUMPRODUCT(($E$14:$E$71=1)*(I14:I71="")),0) | L79: =IF(L78=1,SUMPRODUCT(($E$14:$E$71=1)*(L14:L71="")),0) | O79: =IF(O78=1,SUMPRODUCT(($E$14:$E$71=1)*(O14:O71="")),0) | R79: =IF(R78=1,SUMPRODUCT(($E$14:$E$71=1)*(R14:R71="")),0) | U79: =IF(U78=1,SUMPRODUCT(($E$14:$E$71=1)*(U14:U71="")),0) | X79: =IF(X78=1,SUMPRODUCT(($E$14:$E$71=1)*(X14:X71="")),0)

Sheet ASESOR 02
A1: FORMATO DE MONITOREO COMERCIAL · PREVENTA Y VENTA
A3: Asesor | I3: Fase I (Habeas Data) | P3: =IF($B$7=0,"",IF(SUM(I74,L74,O74,R74,U74,X74)>0,"Reprobada","Aprobada")) | S3: ECU · % sin error | Z3: =IF($B$7=0,"",1-SUM(I75,L75,O75,R75,U75,X75)/$B$7)
A4: Canal | I4: Nota /100 | P4: =IF($B$7=0,"",IF(P3="Reprobada",0,AVERAGE(K73,N73,Q73,T73,W73,Z73)*1)) | S4: ECN · % sin error | Z4: =IF($B$7=0,"",1-SUM(I76,L76,O76,R76,U76,X76)/$B$7)
A5: Gestión | I5: Nota /300 | P5: =IF(P4="","",P4*3) | S5: ECC · % sin error | Z5: =IF($B$7=0,"",1-SUM(I77,L77,O77,R77,U77,X77)/$B$7)
A6: Mes | I6: Nivel | P6: =IF(P4="","",IF(P3="Reprobada","Crítico",LOOKUP(P4/100,'TABLA GENERAL'!$I$7:$I$10,'TABLA GENERAL'!$F$7:$F$10))) | S6: Alerta Dirección | Z6: =IF($B$7=0,"",IF(SUMPRODUCT($AD$14:$AD$71*((I14:I71="NO")+(L14:L71="NO")+(O14:O71="NO")+(R14:R71="NO")+(U14:U71="NO")+(X14:X71="NO")))>0,"SÍ - reportar","No"))
A7: Conversaciones evaluadas | B7: =SUM(I78,L78,O78,R78,U78,X78) | I7: Estado | P7: =IF(P4="","",IF(P3="Reprobada","Reprobado",IF(P4/100>='TABLA GENERAL'!$C$21,"Aprobado","Plan de acción"))) | S7: Casillas por revisar | Z7: =SUM(I79,L79,O79,R79,U79,X79)+COUNTIF(AE14:AE71,"REVISAR")
I9: Conversación 1 | L9: Conversación 2 | O9: Conversación 3 | R9: Conversación 4 | U9: Conversación 5 | X9: Conversación 6
C10: Fecha / ID de la conversación
C11: Modalidad
A13: Código | B13: Dimensión | C13: Descripción | D13: Tipo | E13: Aplica | F13: Peso base | G13: Receptor N/A | H13: Admite N/A | I13: Resultado | J13: Peso estab. | K13: Peso logrado | L13: Resultado | M13: Peso estab. | N13: Peso logrado | O13: Resultado | P13: Peso estab. | Q13: Peso logrado | R13: Resultado | S13: Peso estab. | T13: Peso logrado | U13: Resultado | V13: Peso estab. | W13: Peso logrado | X13: Resultado | Y13: Peso estab. | Z13: Peso logrado | AA13: Σ peso estab. | AB13: Σ peso logrado | AC13: % cumplimiento | AD13: Alerta | AE13: Validación
A14: =CRITERIOS!B2 | B14: =CRITERIOS!C2 | C14: =CRITERIOS!D2 | D14: =CRITERIOS!E2 | E14: =IFERROR(IF(AND(OR(CRITERIOS!F2="Todos",CRITERIOS!F2=$B$4),INDEX(CRITERIOS!H2:J2,MATCH($B$5,VARIABLES!$E$2:$E$4,0))=1),1,0),0) | F14: =IFERROR(IF(E14=1,INDEX(CRITERIOS!K2:M2,MATCH($B$5,VARIABLES!$E$2:$E$4,0)),0),0) | G14: =IF(CRITERIOS!N2="","",CRITERIOS!N2) | H14: =IF(CRITERIOS!O2="","",CRITERIOS!O2) | J14: =IF(OR($E14=0,I$78=0),0,IF(AND(I14="N/A",$G14<>""),0,$F14+SUMPRODUCT(($G$14:$G$71=$A14)*($E$14:$E$71=1)*(I$14:I$71="N/A")*$F$14:$F$71))) | K14: =IF(I14="SI",J14,0) | M14: =IF(OR($E14=0,L$78=0),0,IF(AND(L14="N/A",$G14<>""),0,$F14+SUMPRODUCT(($G$14:$G$71=$A14)*($E$14:$E$71=1)*(L$14:L$71="N/A")*$F$14:$F$71))) | N14: =IF(L14="SI",M14,0) | P14: =IF(OR($E14=0,O$78=0),0,IF(AND(O14="N/A",$G14<>""),0,$F14+SUMPRODUCT(($G$14:$G$71=$A14)*($E$14:$E$71=1)*(O$14:O$71="N/A")*$F$14:$F$71))) | Q14: =IF(O14="SI",P14,0) | S14: =IF(OR($E14=0,R$78=0),0,IF(AND(R14="N/A",$G14<>""),0,$F14+SUMPRODUCT(($G$14:$G$71=$A14)*($E$14:$E$71=1)*(R$14:R$71="N/A")*$F$14:$F$71))) | T14: =IF(R14="SI",S14,0) | V14: =IF(OR($E14=0,U$78=0),0,IF(AND(U14="N/A",$G14<>""),0,$F14+SUMPRODUCT(($G$14:$G$71=$A14)*($E$14:$E$71=1)*(U$14:U$71="N/A")*$F$14:$F$71))) | W14: =IF(U14="SI",V14,0) | Y14: =IF(OR($E14=0,X$78=0),0,IF(AND(X14="N/A",$G14<>""),0,$F14+SUMPRODUCT(($G$14:$G$71=$A14)*($E$14:$E$71=1)*(X$14:X$71="N/A")*$F$14:$F$71))) | Z14: =IF(X14="SI",Y14,0) | AA14: =SUM(J14,M14,P14,S14,V14,Y14) | AB14: =SUM(K14,N14,Q14,T14,W14,Z14) | AC14: =IF(AA14=0,"",AB14/AA14) | AD14: =CRITERIOS!Q2 | AE14: =IF(AND(E14=1,H14<>"X",((I14="N/A")+(L14="N/A")+(O14="N/A")+(R14="N/A")+(U14="N/A")+(X14="N/A"))>0),"REVISAR","")
A15: =CRITERIOS!B3 | B15: =CRITERIOS!C3 | C15: =CRITERIOS!D3 | D15: =CRITERIOS!E3 | E15: =IFERROR(IF(AND(OR(CRITERIOS!F3="Todos",CRITERIOS!F3=$B$4),INDEX(CRITERIOS!H3:J3,MATCH($B$5,VARIABLES!$E$2:$E$4,0))=1),1,0),0) | F15: =IFERROR(IF(E15=1,INDEX(CRITERIOS!K3:M3,MATCH($B$5,VARIABLES!$E$2:$E$4,0)),0),0) | G15: =IF(CRITERIOS!N3="","",CRITERIOS!N3) | H15: =IF(CRITERIOS!O3="","",CRITERIOS!O3) | J15: =IF(OR($E15=0,I$78=0),0,IF(AND(I15="N/A",$G15<>""),0,$F15+SUMPRODUCT(($G$14:$G$71=$A15)*($E$14:$E$71=1)*(I$14:I$71="N/A")*$F$14:$F$71))) | K15: =IF(I15="SI",J15,0) | M15: =IF(OR($E15=0,L$78=0),0,IF(AND(L15="N/A",$G15<>""),0,$F15+SUMPRODUCT(($G$14:$G$71=$A15)*($E$14:$E$71=1)*(L$14:L$71="N/A")*$F$14:$F$71))) | N15: =IF(L15="SI",M15,0) | P15: =IF(OR($E15=0,O$78=0),0,IF(AND(O15="N/A",$G15<>""),0,$F15+SUMPRODUCT(($G$14:$G$71=$A15)*($E$14:$E$71=1)*(O$14:O$71="N/A")*$F$14:$F$71))) | Q15: =IF(O15="SI",P15,0) | S15: =IF(OR($E15=0,R$78=0),0,IF(AND(R15="N/A",$G15<>""),0,$F15+SUMPRODUCT(($G$14:$G$71=$A15)*($E$14:$E$71=1)*(R$14:R$71="N/A")*$F$14:$F$71))) | T15: =IF(R15="SI",S15,0) | V15: =IF(OR($E15=0,U$78=0),0,IF(AND(U15="N/A",$G15<>""),0,$F15+SUMPRODUCT(($G$14:$G$71=$A15)*($E$14:$E$71=1)*(U$14:U$71="N/A")*$F$14:$F$71))) | W15: =IF(U15="SI",V15,0) | Y15: =IF(OR($E15=0,X$78=0),0,IF(AND(X15="N/A",$G15<>""),0,$F15+SUMPRODUCT(($G$14:$G$71=$A15)*($E$14:$E$71=1)*(X$14:X$71="N/A")*$F$14:$F$71))) | Z15: =IF(X15="SI",Y15,0) | AA15: =SUM(J15,M15,P15,S15,V15,Y15) | AB15: =SUM(K15,N15,Q15,T15,W15,Z15) | AC15: =IF(AA15=0,"",AB15/AA15) | AD15: =CRITERIOS!Q3 | AE15: =IF(AND(E15=1,H15<>"X",((I15="N/A")+(L15="N/A")+(O15="N/A")+(R15="N/A")+(U15="N/A")+(X15="N/A"))>0),"REVISAR","")
A16: =CRITERIOS!B4 | B16: =CRITERIOS!C4 | C16: =CRITERIOS!D4 | D16: =CRITERIOS!E4 | E16: =IFERROR(IF(AND(OR(CRITERIOS!F4="Todos",CRITERIOS!F4=$B$4),INDEX(CRITERIOS!H4:J4,MATCH($B$5,VARIABLES!$E$2:$E$4,0))=1),1,0),0) | F16: =IFERROR(IF(E16=1,INDEX(CRITERIOS!K4:M4,MATCH($B$5,VARIABLES!$E$2:$E$4,0)),0),0) | G16: =IF(CRITERIOS!N4="","",CRITERIOS!N4) | H16: =IF(CRITERIOS!O4="","",CRITERIOS!O4) | J16: =IF(OR($E16=0,I$78=0),0,IF(AND(I16="N/A",$G16<>""),0,$F16+SUMPRODUCT(($G$14:$G$71=$A16)*($E$14:$E$71=1)*(I$14:I$71="N/A")*$F$14:$F$71))) | K16: =IF(I16="SI",J16,0) | M16: =IF(OR($E16=0,L$78=0),0,IF(AND(L16="N/A",$G16<>""),0,$F16+SUMPRODUCT(($G$14:$G$71=$A16)*($E$14:$E$71=1)*(L$14:L$71="N/A")*$F$14:$F$71))) | N16: =IF(L16="SI",M16,0) | P16: =IF(OR($E16=0,O$78=0),0,IF(AND(O16="N/A",$G16<>""),0,$F16+SUMPRODUCT(($G$14:$G$71=$A16)*($E$14:$E$71=1)*(O$14:O$71="N/A")*$F$14:$F$71))) | Q16: =IF(O16="SI",P16,0) | S16: =IF(OR($E16=0,R$78=0),0,IF(AND(R16="N/A",$G16<>""),0,$F16+SUMPRODUCT(($G$14:$G$71=$A16)*($E$14:$E$71=1)*(R$14:R$71="N/A")*$F$14:$F$71))) | T16: =IF(R16="SI",S16,0) | V16: =IF(OR($E16=0,U$78=0),0,IF(AND(U16="N/A",$G16<>""),0,$F16+SUMPRODUCT(($G$14:$G$71=$A16)*($E$14:$E$71=1)*(U$14:U$71="N/A")*$F$14:$F$71))) | W16: =IF(U16="SI",V16,0) | Y16: =IF(OR($E16=0,X$78=0),0,IF(AND(X16="N/A",$G16<>""),0,$F16+SUMPRODUCT(($G$14:$G$71=$A16)*($E$14:$E$71=1)*(X$14:X$71="N/A")*$F$14:$F$71))) | Z16: =IF(X16="SI",Y16,0) | AA16: =SUM(J16,M16,P16,S16,V16,Y16) | AB16: =SUM(K16,N16,Q16,T16,W16,Z16) | AC16: =IF(AA16=0,"",AB16/AA16) | AD16: =CRITERIOS!Q4 | AE16: =IF(AND(E16=1,H16<>"X",((I16="N/A")+(L16="N/A")+(O16="N/A")+(R16="N/A")+(U16="N/A")+(X16="N/A"))>0),"REVISAR","")
A17: =CRITERIOS!B5 | B17: =CRITERIOS!C5 | C17: =CRITERIOS!D5 | D17: =CRITERIOS!E5 | E17: =IFERROR(IF(AND(OR(CRITERIOS!F5="Todos",CRITERIOS!F5=$B$4),INDEX(CRITERIOS!H5:J5,MATCH($B$5,VARIABLES!$E$2:$E$4,0))=1),1,0),0) | F17: =IFERROR(IF(E17=1,INDEX(CRITERIOS!K5:M5,MATCH($B$5,VARIABLES!$E$2:$E$4,0)),0),0) | G17: =IF(CRITERIOS!N5="","",CRITERIOS!N5) | H17: =IF(CRITERIOS!O5="","",CRITERIOS!O5) | J17: =IF(OR($E17=0,I$78=0),0,IF(AND(I17="N/A",$G17<>""),0,$F17+SUMPRODUCT(($G$14:$G$71=$A17)*($E$14:$E$71=1)*(I$14:I$71="N/A")*$F$14:$F$71))) | K17: =IF(I17="SI",J17,0) | M17: =IF(OR($E17=0,L$78=0),0,IF(AND(L17="N/A",$G17<>""),0,$F17+SUMPRODUCT(($G$14:$G$71=$A17)*($E$14:$E$71=1)*(L$14:L$71="N/A")*$F$14:$F$71))) | N17: =IF(L17="SI",M17,0) | P17: =IF(OR($E17=0,O$78=0),0,IF(AND(O17="N/A",$G17<>""),0,$F17+SUMPRODUCT(($G$14:$G$71=$A17)*($E$14:$E$71=1)*(O$14:O$71="N/A")*$F$14:$F$71))) | Q17: =IF(O17="SI",P17,0) | S17: =IF(OR($E17=0,R$78=0),0,IF(AND(R17="N/A",$G17<>""),0,$F17+SUMPRODUCT(($G$14:$G$71=$A17)*($E$14:$E$71=1)*(R$14:R$71="N/A")*$F$14:$F$71))) | T17: =IF(R17="SI",S17,0) | V17: =IF(OR($E17=0,U$78=0),0,IF(AND(U17="N/A",$G17<>""),0,$F17+SUMPRODUCT(($G$14:$G$71=$A17)*($E$14:$E$71=1)*(U$14:U$71="N/A")*$F$14:$F$71))) | W17: =IF(U17="SI",V17,0) | Y17: =IF(OR($E17=0,X$78=0),0,IF(AND(X17="N/A",$G17<>""),0,$F17+SUMPRODUCT(($G$14:$G$71=$A17)*($E$14:$E$71=1)*(X$14:X$71="N/A")*$F$14:$F$71))) | Z17: =IF(X17="SI",Y17,0) | AA17: =SUM(J17,M17,P17,S17,V17,Y17) | AB17: =SUM(K17,N17,Q17,T17,W17,Z17) | AC17: =IF(AA17=0,"",AB17/AA17) | AD17: =CRITERIOS!Q5 | AE17: =IF(AND(E17=1,H17<>"X",((I17="N/A")+(L17="N/A")+(O17="N/A")+(R17="N/A")+(U17="N/A")+(X17="N/A"))>0),"REVISAR","")
A18: =CRITERIOS!B6 | B18: =CRITERIOS!C6 | C18: =CRITERIOS!D6 | D18: =CRITERIOS!E6 | E18: =IFERROR(IF(AND(OR(CRITERIOS!F6="Todos",CRITERIOS!F6=$B$4),INDEX(CRITERIOS!H6:J6,MATCH($B$5,VARIABLES!$E$2:$E$4,0))=1),1,0),0) | F18: =IFERROR(IF(E18=1,INDEX(CRITERIOS!K6:M6,MATCH($B$5,VARIABLES!$E$2:$E$4,0)),0),0) | G18: =IF(CRITERIOS!N6="","",CRITERIOS!N6) | H18: =IF(CRITERIOS!O6="","",CRITERIOS!O6) | J18: =IF(OR($E18=0,I$78=0),0,IF(AND(I18="N/A",$G18<>""),0,$F18+SUMPRODUCT(($G$14:$G$71=$A18)*($E$14:$E$71=1)*(I$14:I$71="N/A")*$F$14:$F$71))) | K18: =IF(I18="SI",J18,0) | M18: =IF(OR($E18=0,L$78=0),0,IF(AND(L18="N/A",$G18<>""),0,$F18+SUMPRODUCT(($G$14:$G$71=$A18)*($E$14:$E$71=1)*(L$14:L$71="N/A")*$F$14:$F$71))) | N18: =IF(L18="SI",M18,0) | P18: =IF(OR($E18=0,O$78=0),0,IF(AND(O18="N/A",$G18<>""),0,$F18+SUMPRODUCT(($G$14:$G$71=$A18)*($E$14:$E$71=1)*(O$14:O$71="N/A")*$F$14:$F$71))) | Q18: =IF(O18="SI",P18,0) | S18: =IF(OR($E18=0,R$78=0),0,IF(AND(R18="N/A",$G18<>""),0,$F18+SUMPRODUCT(($G$14:$G$71=$A18)*($E$14:$E$71=1)*(R$14:R$71="N/A")*$F$14:$F$71))) | T18: =IF(R18="SI",S18,0) | V18: =IF(OR($E18=0,U$78=0),0,IF(AND(U18="N/A",$G18<>""),0,$F18+SUMPRODUCT(($G$14:$G$71=$A18)*($E$14:$E$71=1)*(U$14:U$71="N/A")*$F$14:$F$71))) | W18: =IF(U18="SI",V18,0) | Y18: =IF(OR($E18=0,X$78=0),0,IF(AND(X18="N/A",$G18<>""),0,$F18+SUMPRODUCT(($G$14:$G$71=$A18)*($E$14:$E$71=1)*(X$14:X$71="N/A")*$F$14:$F$71))) | Z18: =IF(X18="SI",Y18,0) | AA18: =SUM(J18,M18,P18,S18,V18,Y18) | AB18: =SUM(K18,N18,Q18,T18,W18,Z18) | AC18: =IF(AA18=0,"",AB18/AA18) | AD18: =CRITERIOS!Q6 | AE18: =IF(AND(E18=1,H18<>"X",((I18="N/A")+(L18="N/A")+(O18="N/A")+(R18="N/A")+(U18="N/A")+(X18="N/A"))>0),"REVISAR","")
A19: =CRITERIOS!B7 | B19: =CRITERIOS!C7 | C19: =CRITERIOS!D7 | D19: =CRITERIOS!E7 | E19: =IFERROR(IF(AND(OR(CRITERIOS!F7="Todos",CRITERIOS!F7=$B$4),INDEX(CRITERIOS!H7:J7,MATCH($B$5,VARIABLES!$E$2:$E$4,0))=1),1,0),0) | F19: =IFERROR(IF(E19=1,INDEX(CRITERIOS!K7:M7,MATCH($B$5,VARIABLES!$E$2:$E$4,0)),0),0) | G19: =IF(CRITERIOS!N7="","",CRITERIOS!N7) | H19: =IF(CRITERIOS!O7="","",CRITERIOS!O7) | J19: =IF(OR($E19=0,I$78=0),0,IF(AND(I19="N/A",$G19<>""),0,$F19+SUMPRODUCT(($G$14:$G$71=$A19)*($E$14:$E$71=1)*(I$14:I$71="N/A")*$F$14:$F$71))) | K19: =IF(I19="SI",J19,0) | M19: =IF(OR($E19=0,L$78=0),0,IF(AND(L19="N/A",$G19<>""),0,$F19+SUMPRODUCT(($G$14:$G$71=$A19)*($E$14:$E$71=1)*(L$14:L$71="N/A")*$F$14:$F$71))) | N19: =IF(L19="SI",M19,0) | P19: =IF(OR($E19=0,O$78=0),0,IF(AND(O19="N/A",$G19<>""),0,$F19+SUMPRODUCT(($G$14:$G$71=$A19)*($E$14:$E$71=1)*(O$14:O$71="N/A")*$F$14:$F$71))) | Q19: =IF(O19="SI",P19,0) | S19: =IF(OR($E19=0,R$78=0),0,IF(AND(R19="N/A",$G19<>""),0,$F19+SUMPRODUCT(($G$14:$G$71=$A19)*($E$14:$E$71=1)*(R$14:R$71="N/A")*$F$14:$F$71))) | T19: =IF(R19="SI",S19,0) | V19: =IF(OR($E19=0,U$78=0),0,IF(AND(U19="N/A",$G19<>""),0,$F19+SUMPRODUCT(($G$14:$G$71=$A19)*($E$14:$E$71=1)*(U$14:U$71="N/A")*$F$14:$F$71))) | W19: =IF(U19="SI",V19,0) | Y19: =IF(OR($E19=0,X$78=0),0,IF(AND(X19="N/A",$G19<>""),0,$F19+SUMPRODUCT(($G$14:$G$71=$A19)*($E$14:$E$71=1)*(X$14:X$71="N/A")*$F$14:$F$71))) | Z19: =IF(X19="SI",Y19,0) | AA19: =SUM(J19,M19,P19,S19,V19,Y19) | AB19: =SUM(K19,N19,Q19,T19,W19,Z19) | AC19: =IF(AA19=0,"",AB19/AA19) | AD19: =CRITERIOS!Q7 | AE19: =IF(AND(E19=1,H19<>"X",((I19="N/A")+(L19="N/A")+(O19="N/A")+(R19="N/A")+(U19="N/A")+(X19="N/A"))>0),"REVISAR","")
A20: =CRITERIOS!B8 | B20: =CRITERIOS!C8 | C20: =CRITERIOS!D8 | D20: =CRITERIOS!E8 | E20: =IFERROR(IF(AND(OR(CRITERIOS!F8="Todos",CRITERIOS!F8=$B$4),INDEX(CRITERIOS!H8:J8,MATCH($B$5,VARIABLES!$E$2:$E$4,0))=1),1,0),0) | F20: =IFERROR(IF(E20=1,INDEX(CRITERIOS!K8:M8,MATCH($B$5,VARIABLES!$E$2:$E$4,0)),0),0) | G20: =IF(CRITERIOS!N8="","",CRITERIOS!N8) | H20: =IF(CRITERIOS!O8="","",CRITERIOS!O8) | J20: =IF(OR($E20=0,I$78=0),0,IF(AND(I20="N/A",$G20<>""),0,$F20+SUMPRODUCT(($G$14:$G$71=$A20)*($E$14:$E$71=1)*(I$14:I$71="N/A")*$F$14:$F$71))) | K20: =IF(I20="SI",J20,0) | M20: =IF(OR($E20=0,L$78=0),0,IF(AND(L20="N/A",$G20<>""),0,$F20+SUMPRODUCT(($G$14:$G$71=$A20)*($E$14:$E$71=1)*(L$14:L$71="N/A")*$F$14:$F$71))) | N20: =IF(L20="SI",M20,0) | P20: =IF(OR($E20=0,O$78=0),0,IF(AND(O20="N/A",$G20<>""),0,$F20+SUMPRODUCT(($G$14:$G$71=$A20)*($E$14:$E$71=1)*(O$14:O$71="N/A")*$F$14:$F$71))) | Q20: =IF(O20="SI",P20,0) | S20: =IF(OR($E20=0,R$78=0),0,IF(AND(R20="N/A",$G20<>""),0,$F20+SUMPRODUCT(($G$14:$G$71=$A20)*($E$14:$E$71=1)*(R$14:R$71="N/A")*$F$14:$F$71))) | T20: =IF(R20="SI",S20,0) | V20: =IF(OR($E20=0,U$78=0),0,IF(AND(U20="N/A",$G20<>""),0,$F20+SUMPRODUCT(($G$14:$G$71=$A20)*($E$14:$E$71=1)*(U$14:U$71="N/A")*$F$14:$F$71))) | W20: =IF(U20="SI",V20,0) | Y20: =IF(OR($E20=0,X$78=0),0,IF(AND(X20="N/A",$G20<>""),0,$F20+SUMPRODUCT(($G$14:$G$71=$A20)*($E$14:$E$71=1)*(X$14:X$71="N/A")*$F$14:$F$71))) | Z20: =IF(X20="SI",Y20,0) | AA20: =SUM(J20,M20,P20,S20,V20,Y20) | AB20: =SUM(K20,N20,Q20,T20,W20,Z20) | AC20: =IF(AA20=0,"",AB20/AA20) | AD20: =CRITERIOS!Q8 | AE20: =IF(AND(E20=1,H20<>"X",((I20="N/A")+(L20="N/A")+(O20="N/A")+(R20="N/A")+(U20="N/A")+(X20="N/A"))>0),"REVISAR","")
A21: =CRITERIOS!B9 | B21: =CRITERIOS!C9 | C21: =CRITERIOS!D9 | D21: =CRITERIOS!E9 | E21: =IFERROR(IF(AND(OR(CRITERIOS!F9="Todos",CRITERIOS!F9=$B$4),INDEX(CRITERIOS!H9:J9,MATCH($B$5,VARIABLES!$E$2:$E$4,0))=1),1,0),0) | F21: =IFERROR(IF(E21=1,INDEX(CRITERIOS!K9:M9,MATCH($B$5,VARIABLES!$E$2:$E$4,0)),0),0) | G21: =IF(CRITERIOS!N9="","",CRITERIOS!N9) | H21: =IF(CRITERIOS!O9="","",CRITERIOS!O9) | J21: =IF(OR($E21=0,I$78=0),0,IF(AND(I21="N/A",$G21<>""),0,$F21+SUMPRODUCT(($G$14:$G$71=$A21)*($E$14:$E$71=1)*(I$14:I$71="N/A")*$F$14:$F$71))) | K21: =IF(I21="SI",J21,0) | M21: =IF(OR($E21=0,L$78=0),0,IF(AND(L21="N/A",$G21<>""),0,$F21+SUMPRODUCT(($G$14:$G$71=$A21)*($E$14:$E$71=1)*(L$14:L$71="N/A")*$F$14:$F$71))) | N21: =IF(L21="SI",M21,0) | P21: =IF(OR($E21=0,O$78=0),0,IF(AND(O21="N/A",$G21<>""),0,$F21+SUMPRODUCT(($G$14:$G$71=$A21)*($E$14:$E$71=1)*(O$14:O$71="N/A")*$F$14:$F$71))) | Q21: =IF(O21="SI",P21,0) | S21: =IF(OR($E21=0,R$78=0),0,IF(AND(R21="N/A",$G21<>""),0,$F21+SUMPRODUCT(($G$14:$G$71=$A21)*($E$14:$E$71=1)*(R$14:R$71="N/A")*$F$14:$F$71))) | T21: =IF(R21="SI",S21,0) | V21: =IF(OR($E21=0,U$78=0),0,IF(AND(U21="N/A",$G21<>""),0,$F21+SUMPRODUCT(($G$14:$G$71=$A21)*($E$14:$E$71=1)*(U$14:U$71="N/A")*$F$14:$F$71))) | W21: =IF(U21="SI",V21,0) | Y21: =IF(OR($E21=0,X$78=0),0,IF(AND(X21="N/A",$G21<>""),0,$F21+SUMPRODUCT(($G$14:$G$71=$A21)*($E$14:$E$71=1)*(X$14:X$71="N/A")*$F$14:$F$71))) | Z21: =IF(X21="SI",Y21,0) | AA21: =SUM(J21,M21,P21,S21,V21,Y21) | AB21: =SUM(K21,N21,Q21,T21,W21,Z21) | AC21: =IF(AA21=0,"",AB21/AA21) | AD21: =CRITERIOS!Q9 | AE21: =IF(AND(E21=1,H21<>"X",((I21="N/A")+(L21="N/A")+(O21="N/A")+(R21="N/A")+(U21="N/A")+(X21="N/A"))>0),"REVISAR","")
A22: =CRITERIOS!B10 | B22: =CRITERIOS!C10 | C22: =CRITERIOS!D10 | D22: =CRITERIOS!E10 | E22: =IFERROR(IF(AND(OR(CRITERIOS!F10="Todos",CRITERIOS!F10=$B$4),INDEX(CRITERIOS!H10:J10,MATCH($B$5,VARIABLES!$E$2:$E$4,0))=1),1,0),0) | F22: =IFERROR(IF(E22=1,INDEX(CRITERIOS!K10:M10,MATCH($B$5,VARIABLES!$E$2:$E$4,0)),0),0) | G22: =IF(CRITERIOS!N10="","",CRITERIOS!N10) | H22: =IF(CRITERIOS!O10="","",CRITERIOS!O10) | J22: =IF(OR($E22=0,I$78=0),0,IF(AND(I22="N/A",$G22<>""),0,$F22+SUMPRODUCT(($G$14:$G$71=$A22)*($E$14:$E$71=1)*(I$14:I$71="N/A")*$F$14:$F$71))) | K22: =IF(I22="SI",J22,0) | M22: =IF(OR($E22=0,L$78=0),0,IF(AND(L22="N/A",$G22<>""),0,$F22+SUMPRODUCT(($G$14:$G$71=$A22)*($E$14:$E$71=1)*(L$14:L$71="N/A")*$F$14:$F$71))) | N22: =IF(L22="SI",M22,0) | P22: =IF(OR($E22=0,O$78=0),0,IF(AND(O22="N/A",$G22<>""),0,$F22+SUMPRODUCT(($G$14:$G$71=$A22)*($E$14:$E$71=1)*(O$14:O$71="N/A")*$F$14:$F$71))) | Q22: =IF(O22="SI",P22,0) | S22: =IF(OR($E22=0,R$78=0),0,IF(AND(R22="N/A",$G22<>""),0,$F22+SUMPRODUCT(($G$14:$G$71=$A22)*($E$14:$E$71=1)*(R$14:R$71="N/A")*$F$14:$F$71))) | T22: =IF(R22="SI",S22,0) | V22: =IF(OR($E22=0,U$78=0),0,IF(AND(U22="N/A",$G22<>""),0,$F22+SUMPRODUCT(($G$14:$G$71=$A22)*($E$14:$E$71=1)*(U$14:U$71="N/A")*$F$14:$F$71))) | W22: =IF(U22="SI",V22,0) | Y22: =IF(OR($E22=0,X$78=0),0,IF(AND(X22="N/A",$G22<>""),0,$F22+SUMPRODUCT(($G$14:$G$71=$A22)*($E$14:$E$71=1)*(X$14:X$71="N/A")*$F$14:$F$71))) | Z22: =IF(X22="SI",Y22,0) | AA22: =SUM(J22,M22,P22,S22,V22,Y22) | AB22: =SUM(K22,N22,Q22,T22,W22,Z22) | AC22: =IF(AA22=0,"",AB22/AA22) | AD22: =CRITERIOS!Q10 | AE22: =IF(AND(E22=1,H22<>"X",((I22="N/A")+(L22="N/A")+(O22="N/A")+(R22="N/A")+(U22="N/A")+(X22="N/A"))>0),"REVISAR","")
A23: =CRITERIOS!B11 | B23: =CRITERIOS!C11 | C23: =CRITERIOS!D11 | D23: =CRITERIOS!E11 | E23: =IFERROR(IF(AND(OR(CRITERIOS!F11="Todos",CRITERIOS!F11=$B$4),INDEX(CRITERIOS!H11:J11,MATCH($B$5,VARIABLES!$E$2:$E$4,0))=1),1,0),0) | F23: =IFERROR(IF(E23=1,INDEX(CRITERIOS!K11:M11,MATCH($B$5,VARIABLES!$E$2:$E$4,0)),0),0) | G23: =IF(CRITERIOS!N11="","",CRITERIOS!N11) | H23: =IF(CRITERIOS!O11="","",CRITERIOS!O11) | J23: =IF(OR($E23=0,I$78=0),0,IF(AND(I23="N/A",$G23<>""),0,$F23+SUMPRODUCT(($G$14:$G$71=$A23)*($E$14:$E$71=1)*(I$14:I$71="N/A")*$F$14:$F$71))) | K23: =IF(I23="SI",J23,0) | M23: =IF(OR($E23=0,L$78=0),0,IF(AND(L23="N/A",$G23<>""),0,$F23+SUMPRODUCT(($G$14:$G$71=$A23)*($E$14:$E$71=1)*(L$14:L$71="N/A")*$F$14:$F$71))) | N23: =IF(L23="SI",M23,0) | P23: =IF(OR($E23=0,O$78=0),0,IF(AND(O23="N/A",$G23<>""),0,$F23+SUMPRODUCT(($G$14:$G$71=$A23)*($E$14:$E$71=1)*(O$14:O$71="N/A")*$F$14:$F$71))) | Q23: =IF(O23="SI",P23,0) | S23: =IF(OR($E23=0,R$78=0),0,IF(AND(R23="N/A",$G23<>""),0,$F23+SUMPRODUCT(($G$14:$G$71=$A23)*($E$14:$E$71=1)*(R$14:R$71="N/A")*$F$14:$F$71))) | T23: =IF(R23="SI",S23,0) | V23: =IF(OR($E23=0,U$78=0),0,IF(AND(U23="N/A",$G23<>""),0,$F23+SUMPRODUCT(($G$14:$G$71=$A23)*($E$14:$E$71=1)*(U$14:U$71="N/A")*$F$14:$F$71))) | W23: =IF(U23="SI",V23,0) | Y23: =IF(OR($E23=0,X$78=0),0,IF(AND(X23="N/A",$G23<>""),0,$F23+SUMPRODUCT(($G$14:$G$71=$A23)*($E$14:$E$71=1)*(X$14:X$71="N/A")*$F$14:$F$71))) | Z23: =IF(X23="SI",Y23,0) | AA23: =SUM(J23,M23,P23,S23,V23,Y23) | AB23: =SUM(K23,N23,Q23,T23,W23,Z23) | AC23: =IF(AA23=0,"",AB23/AA23) | AD23: =CRITERIOS!Q11 | AE23: =IF(AND(E23=1,H23<>"X",((I23="N/A")+(L23="N/A")+(O23="N/A")+(R23="N/A")+(U23="N/A")+(X23="N/A"))>0),"REVISAR","")
A24: =CRITERIOS!B12 | B24: =CRITERIOS!C12 | C24: =CRITERIOS!D12 | D24: =CRITERIOS!E12 | E24: =IFERROR(IF(AND(OR(CRITERIOS!F12="Todos",CRITERIOS!F12=$B$4),INDEX(CRITERIOS!H12:J12,MATCH($B$5,VARIABLES!$E$2:$E$4,0))=1),1,0),0) | F24: =IFERROR(IF(E24=1,INDEX(CRITERIOS!K12:M12,MATCH($B$5,VARIABLES!$E$2:$E$4,0)),0),0) | G24: =IF(CRITERIOS!N12="","",CRITERIOS!N12) | H24: =IF(CRITERIOS!O12="","",CRITERIOS!O12) | J24: =IF(OR($E24=0,I$78=0),0,IF(AND(I24="N/A",$G24<>""),0,$F24+SUMPRODUCT(($G$14:$G$71=$A24)*($E$14:$E$71=1)*(I$14:I$71="N/A")*$F$14:$F$71))) | K24: =IF(I24="SI",J24,0) | M24: =IF(OR($E24=0,L$78=0),0,IF(AND(L24="N/A",$G24<>""),0,$F24+SUMPRODUCT(($G$14:$G$71=$A24)*($E$14:$E$71=1)*(L$14:L$71="N/A")*$F$14:$F$71))) | N24: =IF(L24="SI",M24,0) | P24: =IF(OR($E24=0,O$78=0),0,IF(AND(O24="N/A",$G24<>""),0,$F24+SUMPRODUCT(($G$14:$G$71=$A24)*($E$14:$E$71=1)*(O$14:O$71="N/A")*$F$14:$F$71))) | Q24: =IF(O24="SI",P24,0) | S24: =IF(OR($E24=0,R$78=0),0,IF(AND(R24="N/A",$G24<>""),0,$F24+SUMPRODUCT(($G$14:$G$71=$A24)*($E$14:$E$71=1)*(R$14:R$71="N/A")*$F$14:$F$71))) | T24: =IF(R24="SI",S24,0) | V24: =IF(OR($E24=0,U$78=0),0,IF(AND(U24="N/A",$G24<>""),0,$F24+SUMPRODUCT(($G$14:$G$71=$A24)*($E$14:$E$71=1)*(U$14:U$71="N/A")*$F$14:$F$71))) | W24: =IF(U24="SI",V24,0) | Y24: =IF(OR($E24=0,X$78=0),0,IF(AND(X24="N/A",$G24<>""),0,$F24+SUMPRODUCT(($G$14:$G$71=$A24)*($E$14:$E$71=1)*(X$14:X$71="N/A")*$F$14:$F$71))) | Z24: =IF(X24="SI",Y24,0) | AA24: =SUM(J24,M24,P24,S24,V24,Y24) | AB24: =SUM(K24,N24,Q24,T24,W24,Z24) | AC24: =IF(AA24=0,"",AB24/AA24) | AD24: =CRITERIOS!Q12 | AE24: =IF(AND(E24=1,H24<>"X",((I24="N/A")+(L24="N/A")+(O24="N/A")+(R24="N/A")+(U24="N/A")+(X24="N/A"))>0),"REVISAR","")
A25: =CRITERIOS!B13 | B25: =CRITERIOS!C13 | C25: =CRITERIOS!D13 | D25: =CRITERIOS!E13 | E25: =IFERROR(IF(AND(OR(CRITERIOS!F13="Todos",CRITERIOS!F13=$B$4),INDEX(CRITERIOS!H13:J13,MATCH($B$5,VARIABLES!$E$2:$E$4,0))=1),1,0),0) | F25: =IFERROR(IF(E25=1,INDEX(CRITERIOS!K13:M13,MATCH($B$5,VARIABLES!$E$2:$E$4,0)),0),0) | G25: =IF(CRITERIOS!N13="","",CRITERIOS!N13) | H25: =IF(CRITERIOS!O13="","",CRITERIOS!O13) | J25: =IF(OR($E25=0,I$78=0),0,IF(AND(I25="N/A",$G25<>""),0,$F25+SUMPRODUCT(($G$14:$G$71=$A25)*($E$14:$E$71=1)*(I$14:I$71="N/A")*$F$14:$F$71))) | K25: =IF(I25="SI",J25,0) | M25: =IF(OR($E25=0,L$78=0),0,IF(AND(L25="N/A",$G25<>""),0,$F25+SUMPRODUCT(($G$14:$G$71=$A25)*($E$14:$E$71=1)*(L$14:L$71="N/A")*$F$14:$F$71))) | N25: =IF(L25="SI",M25,0) | P25: =IF(OR($E25=0,O$78=0),0,IF(AND(O25="N/A",$G25<>""),0,$F25+SUMPRODUCT(($G$14:$G$71=$A25)*($E$14:$E$71=1)*(O$14:O$71="N/A")*$F$14:$F$71))) | Q25: =IF(O25="SI",P25,0) | S25: =IF(OR($E25=0,R$78=0),0,IF(AND(R25="N/A",$G25<>""),0,$F25+SUMPRODUCT(($G$14:$G$71=$A25)*($E$14:$E$71=1)*(R$14:R$71="N/A")*$F$14:$F$71))) | T25: =IF(R25="SI",S25,0) | V25: =IF(OR($E25=0,U$78=0),0,IF(AND(U25="N/A",$G25<>""),0,$F25+SUMPRODUCT(($G$14:$G$71=$A25)*($E$14:$E$71=1)*(U$14:U$71="N/A")*$F$14:$F$71))) | W25: =IF(U25="SI",V25,0) | Y25: =IF(OR($E25=0,X$78=0),0,IF(AND(X25="N/A",$G25<>""),0,$F25+SUMPRODUCT(($G$14:$G$71=$A25)*($E$14:$E$71=1)*(X$14:X$71="N/A")*$F$14:$F$71))) | Z25: =IF(X25="SI",Y25,0) | AA25: =SUM(J25,M25,P25,S25,V25,Y25) | AB25: =SUM(K25,N25,Q25,T25,W25,Z25) | AC25: =IF(AA25=0,"",AB25/AA25) | AD25: =CRITERIOS!Q13 | AE25: =IF(AND(E25=1,H25<>"X",((I25="N/A")+(L25="N/A")+(O25="N/A")+(R25="N/A")+(U25="N/A")+(X25="N/A"))>0),"REVISAR","")
